Workbook

Sheet 게임기록
A1: 날짜 | B1: =TODAY()
A2: 닉네임+점수 입력 → 기록 자동 반영 → 승점순위·출석 확인 (Excel 365)
A3: 1게임 | G3: 2게임 | M3: 3게임
A4: # | B4: 닉네임 | C4: 바이인 | D4: 리바인 | E4: 머니인 | G4: # | H4: 닉네임 | I4: 바이인 | J4: 리바인 | K4: 머니인 | M4: # | N4: 닉네임 | O4: 바이인 | P4: 리바인 | Q4: 머니인
A5: 1 | G5: 1 | M5: 1
A6: 2 | G6: 2 | M6: 2
A7: 3 | G7: 3 | M7: 3
A8: 4 | G8: 4 | M8: 4
A9: 5 | G9: 5 | M9: 5
A10: 6 | G10: 6 | M10: 6
A11: 7 | G11: 7 | M11: 7
A12: 8 | G12: 8 | M12: 8
A13: 9 | G13: 9 | M13: 9
A14: 10 | G14: 10 | M14: 10
A15: 11 | G15: 11 | M15: 11
A16: 12 | G16: 12 | M16: 12
... A24: 20 | G24: 20 | M24: 20
A26: 4게임 | G26: 5게임 | M26: 6게임
A27: # | B27: 닉네임 | C27: 바이인 | D27: 리바인 | E27: 머니인 | G27: # | H27: 닉네임 | I27: 바이인 | J27: 리바인 | K27: 머니인 | M27: # | N27: 닉네임 | O27: 바이인 | P27: 리바인 | Q27: 머니인
A28: 1 | G28: 1 | M28: 1
A29: 2 | G29: 2 | M29: 2
A30: 3 | G30: 3 | M30: 3
A31: 4 | G31: 4 | M31: 4
A32: 5 | G32: 5 | M32: 5
A33: 6 | G33: 6 | M33: 6
A34: 7 | G34: 7 | M34: 7
A35: 8 | G35: 8 | M35: 8
A36: 9 | G36: 9 | M36: 9
A37: 10 | G37: 10 | M37: 10
A38: 11 | G38: 11 | M38: 11
A39: 12 | G39: 12 | M39: 12
... A47: 20 | G47: 20 | M47: 20
A49: 7게임 | G49: 8게임 | M49: 9게임
A50: # | B50: 닉네임 | C50: 바이인 | D50: 리바인 | E50: 머니인 | G50: # | H50: 닉네임 | I50: 바이인 | J50: 리바인 | K50: 머니인 | M50: # | N50: 닉네임 | O50: 바이인 | P50: 리바인 | Q50: 머니인
A51: 1 | G51: 1 | M51: 1
A52: 2 | G52: 2 | M52: 2
A53: 3 | G53: 3 | M53: 3
A54: 4 | G54: 4 | M54: 4
A55: 5 | G55: 5 | M55: 5
A56: 6 | G56: 6 | M56: 6
...

Sheet 기록
A1: 날짜 | B1: 게임 | C1: 닉네임 | D1: 바이인 | E1: 리바인 | F1: 머니인 | G1: 합계
A2: =IF(AND('게임기록'!$B$5<>"",'게임기록'!$C$5+'게임기록'!$D$5+'게임기록'!$E$5>0),'게임기록'!$B$1,"") | B2: =IF($A2="","",1) | C2: =IF($A2="","",'게임기록'!$B$5) | D2: =IF($A2="","",'게임기록'!$C$5) | E2: =IF($A2="","",'게임기록'!$D$5) | F2: =IF($A2="","",'게임기록'!$E$5) | G2: =IF($A2="","",'게임기록'!$C$5+'게임기록'!$D$5+'게임기록'!$E$5)
A3: =IF(AND('게임기록'!$B$6<>"",'게임기록'!$C$6+'게임기록'!$D$6+'게임기록'!$E$6>0),'게임기록'!$B$1,"") | B3: =IF($A3="","",1) | C3: =IF($A3="","",'게임기록'!$B$6) | D3: =IF($A3="","",'게임기록'!$C$6) | E3: =IF($A3="","",'게임기록'!$D$6) | F3: =IF($A3="","",'게임기록'!$E$6) | G3: =IF($A3="","",'게임기록'!$C$6+'게임기록'!$D$6+'게임기록'!$E$6)
A4: =IF(AND('게임기록'!$B$7<>"",'게임기록'!$C$7+'게임기록'!$D$7+'게임기록'!$E$7>0),'게임기록'!$B$1,"") | B4: =IF($A4="","",1) | C4: =IF($A4="","",'게임기록'!$B$7) | D4: =IF($A4="","",'게임기록'!$C$7) | E4: =IF($A4="","",'게임기록'!$D$7) | F4: =IF($A4="","",'게임기록'!$E$7) | G4: =IF($A4="","",'게임기록'!$C$7+'게임기록'!$D$7+'게임기록'!$E$7)
A5: =IF(AND('게임기록'!$B$8<>"",'게임기록'!$C$8+'게임기록'!$D$8+'게임기록'!$E$8>0),'게임기록'!$B$1,"") | B5: =IF($A5="","",1) | C5: =IF($A5="","",'게임기록'!$B$8) | D5: =IF($A5="","",'게임기록'!$C$8) | E5: =IF($A5="","",'게임기록'!$D$8) | F5: =IF($A5="","",'게임기록'!$E$8) | G5: =IF($A5="","",'게임기록'!$C$8+'게임기록'!$D$8+'게임기록'!$E$8)
A6: =IF(AND('게임기록'!$B$9<>"",'게임기록'!$C$9+'게임기록'!$D$9+'게임기록'!$E$9>0),'게임기록'!$B$1,"") | B6: =IF($A6="","",1) | C6: =IF($A6="","",'게임기록'!$B$9) | D6: =IF($A6="","",'게임기록'!$C$9) | E6: =IF($A6="","",'게임기록'!$D$9) | F6: =IF($A6="","",'게임기록'!$E$9) | G6: =IF($A6="","",'게임기록'!$C$9+'게임기록'!$D$9+'게임기록'!$E$9)
A7: =IF(AND('게임기록'!$B$10<>"",'게임기록'!$C$10+'게임기록'!$D$10+'게임기록'!$E$10>0),'게임기록'!$B$1,"") | B7: =IF($A7="","",1) | C7: =IF($A7="","",'게임기록'!$B$10) | D7: =IF($A7="","",'게임기록'!$C$10) | E7: =IF($A7="","",'게임기록'!$D$10) | F7: =IF($A7="","",'게임기록'!$E$10) | G7: =IF($A7="","",'게임기록'!$C$10+'게임기록'!$D$10+'게임기록'!$E$10)
A8: =IF(AND('게임기록'!$B$11<>"",'게임기록'!$C$11+'게임기록'!$D$11+'게임기록'!$E$11>0),'게임기록'!$B$1,"") | B8: =IF($A8="","",1) | C8: =IF($A8="","",'게임기록'!$B$11) | D8: =IF($A8="","",'게임기록'!$C$11) | E8: =IF($A8="","",'게임기록'!$D$11) | F8: =IF($A8="","",'게임기록'!$E$11) | G8: =IF($A8="","",'게임기록'!$C$11+'게임기록'!$D$11+'게임기록'!$E$11)
A9: =IF(AND('게임기록'!$B$12<>"",'게임기록'!$C$12+'게임기록'!$D$12+'게임기록'!$E$12>0),'게임기록'!$B$1,"") | B9: =IF($A9="","",1) | C9: =IF($A9="","",'게임기록'!$B$12) | D9: =IF($A9="","",'게임기록'!$C$12) | E9: =IF($A9="","",'게임기록'!$D$12) | F9: =IF($A9="","",'게임기록'!$E$12) | G9: =IF($A9="","",'게임기록'!$C$12+'게임기록'!$D$12+'게임기록'!$E$12)
A10: =IF(AND('게임기록'!$B$13<>"",'게임기록'!$C$13+'게임기록'!$D$13+'게임기록'!$E$13>0),'게임기록'!$B$1,"") | B10: =IF($A10="","",1) | C10: =IF($A10="","",'게임기록'!$B$13) | D10: =IF($A10="","",'게임기록'!$C$13) | E10: =IF($A10="","",'게임기록'!$D$13) | F10: =IF($A10="","",'게임기록'!$E$13) | G10: =IF($A10="","",'게임기록'!$C$13+'게임기록'!$D$13+'게임기록'!$E$13)
A11: =IF(AND('게임기록'!$B$14<>"",'게임기록'!$C$14+'게임기록'!$D$14+'게임기록'!$E$14>0),'게임기록'!$B$1,"") | B11: =IF($A11="","",1) | C11: =IF($A11="","",'게임기록'!$B$14) | D11: =IF($A11="","",'게임기록'!$C$14) | E11: =IF($A11="","",'게임기록'!$D$14) | F11: =IF($A11="","",'게임기록'!$E$14) | G11: =IF($A11="","",'게임기록'!$C$14+'게임기록'!$D$14+'게임기록'!$E$14)
A12: =IF(AND('게임기록'!$B$15<>"",'게임기록'!$C$15+'게임기록'!$D$15+'게임기록'!$E$15>0),'게임기록'!$B$1,"") | B12: =IF($A12="","",1) | C12: =IF($A12="","",'게임기록'!$B$15) | D12: =IF($A12="","",'게임기록'!$C$15) | E12: =IF($A12="","",'게임기록'!$D$15) | F12: =IF($A12="","",'게임기록'!$E$15) | G12: =IF($A12="","",'게임기록'!$C$15+'게임기록'!$D$15+'게임기록'!$E$15)
A13: =IF(AND('게임기록'!$B$16<>"",'게임기록'!$C$16+'게임기록'!$D$16+'게임기록'!$E$16>0),'게임기록'!$B$1,"") | B13: =IF($A13="","",1) | C13: =IF($A13="","",'게임기록'!$B$16) | D13: =IF($A13="","",'게임기록'!$C$16) | E13: =IF($A13="","",'게임기록'!$D$16) | F13: =IF($A13="","",'게임기록'!$E$16) | G13: =IF($A13="","",'게임기록'!$C$16+'게임기록'!$D$16+'게임기록'!$E$16)
A14: =IF(AND('게임기록'!$B$17<>"",'게임기록'!$C$17+'게임기록'!$D$17+'게임기록'!$E$17>0),'게임기록'!$B$1,"") | B14: =IF($A14="","",1) | C14: =IF($A14="","",'게임기록'!$B$17) | D14: =IF($A14="","",'게임기록'!$C$17) | E14: =IF($A14="","",'게임기록'!$D$17) | F14: =IF($A14="","",'게임기록'!$E$17) | G14: =IF($A14="","",'게임기록'!$C$17+'게임기록'!$D$17+'게임기록'!$E$17)
A15: =IF(AND('게임기록'!$B$18<>"",'게임기록'!$C$18+'게임기록'!$D$18+'게임기록'!$E$18>0),'게임기록'!$B$1,"") | B15: =IF($A15="","",1) | C15: =IF($A15="","",'게임기록'!$B$18) | D15: =IF($A15="","",'게임기록'!$C$18) | E15: =IF($A15="","",'게임기록'!$D$18) | F15: =IF($A15="","",'게임기록'!$E$18) | G15: =IF($A15="","",'게임기록'!$C$18+'게임기록'!$D$18+'게임기록'!$E$18)
A16: =IF(AND('게임기록'!$B$19<>"",'게임기록'!$C$19+'게임기록'!$D$19+'게임기록'!$E$19>0),'게임기록'!$B$1,"") | B16: =IF($A16="","",1) | C16: =IF($A16="","",'게임기록'!$B$19) | D16: =IF($A16="","",'게임기록'!$C$19) | E16: =IF($A16="","",'게임기록'!$D$19) | F16: =IF($A16="","",'게임기록'!$E$19) | G16: =IF($A16="","",'게임기록'!$C$19+'게임기록'!$D$19+'게임기록'!$E$19)
A17: =IF(AND('게임기록'!$B$20<>"",'게임기록'!$C$20+'게임기록'!$D$20+'게임기록'!$E$20>0),'게임기록'!$B$1,"") | B17: =IF($A17="","",1) | C17: =IF($A17="","",'게임기록'!$B$20) | D17: =IF($A17="","",'게임기록'!$C$20) | E17: =IF($A17="","",'게임기록'!$D$20) | F17: =IF($A17="","",'게임기록'!$E$20) | G17: =IF($A17="","",'게임기록'!$C$20+'게임기록'!$D$20+'게임기록'!$E$20)
A18: =IF(AND('게임기록'!$B$21<>"",'게임기록'!$C$21+'게임기록'!$D$21+'게임기록'!$E$21>0),'게임기록'!$B$1,"") | B18: =IF($A18="","",1) | C18: =IF($A18="","",'게임기록'!$B$21) | D18: =IF($A18="","",'게임기록'!$C$21) | E18: =IF($A18="","",'게임기록'!$D$21) | F18: =IF($A18="","",'게임기록'!$E$21) | G18: =IF($A18="","",'게임기록'!$C$21+'게임기록'!$D$21+'게임기록'!$E$21)
A19: =IF(AND('게임기록'!$B$22<>"",'게임기록'!$C$22+'게임기록'!$D$22+'게임기록'!$E$22>0),'게임기록'!$B$1,"") | B19: =IF($A19="","",1) | C19: =IF($A19="","",'게임기록'!$B$22) | D19: =IF($A19="","",'게임기록'!$C$22) | E19: =IF($A19="","",'게임기록'!$D$22) | F19: =IF($A19="","",'게임기록'!$E$22) | G19: =IF($A19="","",'게임기록'!$C$22+'게임기록'!$D$22+'게임기록'!$E$22)
A20: =IF(AND('게임기록'!$B$23<>"",'게임기록'!$C$23+'게임기록'!$D$23+'게임기록'!$E$23>0),'게임기록'!$B$1,"") | B20: =IF($A20="","",1) | C20: =IF($A20="","",'게임기록'!$B$23) | D20: =IF($A20="","",'게임기록'!$C$23) | E20: =IF($A20="","",'게임기록'!$D$23) | F20: =IF($A20="","",'게임기록'!$E$23) | G20: =IF($A20="","",'게임기록'!$C$23+'게임기록'!$D$23+'게임기록'!$E$23)
A21: =IF(AND('게임기록'!$B$24<>"",'게임기록'!$C$24+'게임기록'!$D$24+'게임기록'!$E$24>0),'게임기록'!$B$1,"") | B21: =IF($A21="","",1) | C21: =IF($A21="","",'게임기록'!$B$24) | D21: =IF($A21="","",'게임기록'!$C$24) | E21: =IF($A21="","",'게임기록'!$D$24) | F21: =IF($A21="","",'게임기록'!$E$24) | G21: =IF($A21="","",'게임기록'!$C$24+'게임기록'!$D$24+'게임기록'!$E$24)
A22: =IF(AND('게임기록'!$H$5<>"",'게임기록'!$I$5+'게임기록'!$J$5+'게임기록'!$K$5>0),'게임기록'!$B$1,"") | B22: =IF($A22="","",2) | C22: =IF($A22="","",'게임기록'!$H$5) | D22: =IF($A22="","",'게임기록'!$I$5) | E22: =IF($A22="","",'게임기록'!$J$5) | F22: =IF($A22="","",'게임기록'!$K$5) | G22: =IF($A22="","",'게임기록'!$I$5+'게임기록'!$J$5+'게임기록'!$K$5)
A23: =IF(AND('게임기록'!$H$6<>"",'게임기록'!$I$6+'게임기록'!$J$6+'게임기록'!$K$6>0),'게임기록'!$B$1,"") | B23: =IF($A23="","",2) | C23: =IF($A23="","",'게임기록'!$H$6) | D23: =IF($A23="","",'게임기록'!$I$6) | E23: =IF($A23="","",'게임기록'!$J$6) | F23: =IF($A23="","",'게임기록'!$K$6) | G23: =IF($A23="","",'게임기록'!$I$6+'게임기록'!$J$6+'게임기록'!$K$6)
A24: =IF(AND('게임기록'!$H$7<>"",'게임기록'!$I$7+'게임기록'!$J$7+'게임기록'!$K$7>0),'게임기록'!$B$1,"") | B24: =IF($A24="","",2) | C24: =IF($A24="","",'게임기록'!$H$7) | D24: =IF($A24="","",'게임기록'!$I$7) | E24: =IF($A24="","",'게임기록'!$J$7) | F24: =IF($A24="","",'게임기록'!$K$7) | G24: =IF($A24="","",'게임기록'!$I$7+'게임기록'!$J$7+'게임기록'!$K$7)
A25: =IF(AND('게임기록'!$H$8<>"",'게임기록'!$I$8+'게임기록'!$J$8+'게임기록'!$K$8>0),'게임기록'!$B$1,"") | B25: =IF($A25="","",2) | C25: =IF($A25="","",'게임기록'!$H$8) | D25: =IF($A25="","",'게임기록'!$I$8) | E25: =IF($A25="","",'게임기록'!$J$8) | F25: =IF($A25="","",'게임기록'!$K$8) | G25: =IF($A25="","",'게임기록'!$I$8+'게임기록'!$J$8+'게임기록'!$K$8)
A26: =IF(AND('게임기록'!$H$9<>"",'게임기록'!$I$9+'게임기록'!$J$9+'게임기록'!$K$9>0),'게임기록'!$B$1,"") | B26: =IF($A26="","",2) | C26: =IF($A26="","",'게임기록'!$H$9) | D26: =IF($A26="","",'게임기록'!$I$9) | E26: =IF($A26="","",'게임기록'!$J$9) | F26: =IF($A26="","",'게임기록'!$K$9) | G26: =IF($A26="","",'게임기록'!$I$9+'게임기록'!$J$9+'게임기록'!$K$9)
A27: =IF(AND('게임기록'!$H$10<>"",'게임기록'!$I$10+'게임기록'!$J$10+'게임기록'!$K$10>0),'게임기록'!$B$1,"") | B27: =IF($A27="","",2) | C27: =IF($A27="","",'게임기록'!$H$10) | D27: =IF($A27="","",'게임기록'!$I$10) | E27: =IF($A27="","",'게임기록'!$J$10) | F27: =IF($A27="","",'게임기록'!$K$10) | G27: =IF($A27="","",'게임기록'!$I$10+'게임기록'!$J$10+'게임기록'!$K$10)
A28: =IF(AND('게임기록'!$H$11<>"",'게임기록'!$I$11+'게임기록'!$J$11+'게임기록'!$K$11>0),'게임기록'!$B$1,"") | B28: =IF($A28="","",2) | C28: =IF($A28="","",'게임기록'!$H$11) | D28: =IF($A28="","",'게임기록'!$I$11) | E28: =IF($A28="","",'게임기록'!$J$11) | F28: =IF($A28="","",'게임기록'!$K$11) | G28: =IF($A28="","",'게임기록'!$I$11+'게임기록'!$J$11+'게임기록'!$K$11)
A29: =IF(AND('게임기록'!$H$12<>"",'게임기록'!$I$12+'게임기록'!$J$12+'게임기록'!$K$12>0),'게임기록'!$B$1,"") | B29: =IF($A29="","",2) | C29: =IF($A29="","",'게임기록'!$H$12) | D29: =IF($A29="","",'게임기록'!$I$12) | E29: =IF($A29="","",'게임기록'!$J$12) | F29: =IF($A29="","",'게임기록'!$K$12) | G29: =IF($A29="","",'게임기록'!$I$12+'게임기록'!$J$12+'게임기록'!$K$12)
A30: =IF(AND('게임기록'!$H$13<>"",'게임기록'!$I$13+'게임기록'!$J$13+'게임기록'!$K$13>0),'게임기록'!$B$1,"") | B30: =IF($A30="","",2) | C30: =IF($A30="","",'게임기록'!$H$13) | D30: =IF($A30="","",'게임기록'!$I$13) | E30: =IF($A30="","",'게임기록'!$J$13) | F30: =IF($A30="","",'게임기록'!$K$13) | G30: =IF($A30="","",'게임기록'!$I$13+'게임기록'!$J$13+'게임기록'!$K$13)
A31: =IF(AND('게임기록'!$H$14<>"",'게임기록'!$I$14+'게임기록'!$J$14+'게임기록'!$K$14>0),'게임기록'!$B$1,"") | B31: =IF($A31="","",2) | C31: =IF($A31="","",'게임기록'!$H$14) | D31: =IF($A31="","",'게임기록'!$I$14) | E31: =IF($A31="","",'게임기록'!$J$14) | F31: =IF($A31="","",'게임기록'!$K$14) | G31: =IF($A31="","",'게임기록'!$I$14+'게임기록'!$J$14+'게임기록'!$K$14)
A32: =IF(AND('게임기록'!$H$15<>"",'게임기록'!$I$15+'게임기록'!$J$15+'게임기록'!$K$15>0),'게임기록'!$B$1,"") | B32: =IF($A32="","",2) | C32: =IF($A32="","",'게임기록'!$H$15) | D32: =IF($A32="","",'게임기록'!$I$15) | E32: =IF($A32="","",'게임기록'!$J$15) | F32: =IF($A32="","",'게임기록'!$K$15) | G32: =IF($A32="","",'게임기록'!$I$15+'게임기록'!$J$15+'게임기록'!$K$15)
A33: =IF(AND('게임기록'!$H$16<>"",'게임기록'!$I$16+'게임기록'!$J$16+'게임기록'!$K$16>0),'게임기록'!$B$1,"") | B33: =IF($A33="","",2) | C33: =IF($A33="","",'게임기록'!$H$16) | D33: =IF($A33="","",'게임기록'!$I$16) | E33: =IF($A33="","",'게임기록'!$J$16) | F33: =IF($A33="","",'게임기록'!$K$16) | G33: =IF($A33="","",'게임기록'!$I$16+'게임기록'!$J$16+'게임기록'!$K$16)
A34: =IF(AND('게임기록'!$H$17<>"",'게임기록'!$I$17+'게임기록'!$J$17+'게임기록'!$K$17>0),'게임기록'!$B$1,"") | B34: =IF($A34="","",2) | C34: =IF($A34="","",'게임기록'!$H$17) | D34: =IF($A34="","",'게임기록'!$I$17) | E34: =IF($A34="","",'게임기록'!$J$17) | F34: =IF($A34="","",'게임기록'!$K$17) | G34: =IF($A34="","",'게임기록'!$I$17+'게임기록'!$J$17+'게임기록'!$K$17)
A35: =IF(AND('게임기록'!$H$18<>"",'게임기록'!$I$18+'게임기록'!$J$18+'게임기록'!$K$18>0),'게임기록'!$B$1,"") | B35: =IF($A35="","",2) | C35: =IF($A35="","",'게임기록'!$H$18) | D35: =IF($A35="","",'게임기록'!$I$18) | E35: =IF($A35="","",'게임기록'!$J$18) | F35: =IF($A35="","",'게임기록'!$K$18) | G35: =IF($A35="","",'게임기록'!$I$18+'게임기록'!$J$18+'게임기록'!$K$18)
A36: =IF(AND('게임기록'!$H$19<>"",'게임기록'!$I$19+'게임기록'!$J$19+'게임기록'!$K$19>0),'게임기록'!$B$1,"") | B36: =IF($A36="","",2) | C36: =IF($A36="","",'게임기록'!$H$19) | D36: =IF($A36="","",'게임기록'!$I$19) | E36: =IF($A36="","",'게임기록'!$J$19) | F36: =IF($A36="","",'게임기록'!$K$19) | G36: =IF($A36="","",'게임기록'!$I$19+'게임기록'!$J$19+'게임기록'!$K$19)
A37: =IF(AND('게임기록'!$H$20<>"",'게임기록'!$I$20+'게임기록'!$J$20+'게임기록'!$K$20>0),'게임기록'!$B$1,"") | B37: =IF($A37="","",2) | C37: =IF($A37="","",'게임기록'!$H$20) | D37: =IF($A37="","",'게임기록'!$I$20) | E37: =IF($A37="","",'게임기록'!$J$20) | F37: =IF($A37="","",'게임기록'!$K$20) | G37: =IF($A37="","",'게임기록'!$I$20+'게임기록'!$J$20+'게임기록'!$K$20)
A38: =IF(AND('게임기록'!$H$21<>"",'게임기록'!$I$21+'게임기록'!$J$21+'게임기록'!$K$21>0),'게임기록'!$B$1,"") | B38: =IF($A38="","",2) | C38: =IF($A38="","",'게임기록'!$H$21) | D38: =IF($A38="","",'게임기록'!$I$21) | E38: =IF($A38="","",'게임기록'!$J$21) | F38: =IF($A38="","",'게임기록'!$K$21) | G38: =IF($A38="","",'게임기록'!$I$21+'게임기록'!$J$21+'게임기록'!$K$21)
A39: =IF(AND('게임기록'!$H$22<>"",'게임기록'!$I$22+'게임기록'!$J$22+'게임기록'!$K$22>0),'게임기록'!$B$1,"") | B39: =IF($A39="","",2) | C39: =IF($A39="","",'게임기록'!$H$22) | D39: =IF($A39="","",'게임기록'!$I$22) | E39: =IF($A39="","",'게임기록'!$J$22) | F39: =IF($A39="","",'게임기록'!$K$22) | G39: =IF($A39="","",'게임기록'!$I$22+'게임기록'!$J$22+'게임기록'!$K$22)
A40: =IF(AND('게임기록'!$H$23<>"",'게임기록'!$I$23+'게임기록'!$J$23+'게임기록'!$K$23>0),'게임기록'!$B$1,"") | B40: =IF($A40="","",2) | C40: =IF($A40="","",'게임기록'!$H$23) | D40: =IF($A40="","",'게임기록'!$I$23) | E40: =IF($A40="","",'게임기록'!$J$23) | F40: =IF($A40="","",'게임기록'!$K$23) | G40: =IF($A40="","",'게임기록'!$I$23+'게임기록'!$J$23+'게임기록'!$K$23)
...

Sheet 승점순위
A1: 기간 시작 | B1: =DATE(YEAR(TODAY()),MONTH(TODAY()),1)
A2: 기간 종료 | B2: =EOMONTH(B1,0)
A3: 총점 내림차순 · 출석일=서로 다른 날짜 수
A4: 순위 | B4: 닉네임 | C4: 총점 | D4: 출석일
A5: =IFERROR(INDEX($N$5:$Q$204,1,1),"") | B5: =IFERROR(INDEX($N$5:$Q$204,1,2),"") | C5: =IFERROR(INDEX($N$5:$Q$204,1,3),"") | D5: =IFERROR(INDEX($N$5:$Q$204,1,4),"") | H5: =IF(I5="","",1) | I5: =IFERROR(INDEX(_xlfn.UNIQUE(_xlfn.FILTER('기록'!$C$2:$C$181,('기록'!$C$2:$C$181<>"")*('기록'!$A$2:$A$181>=$B$1)*('기록'!$A$2:$A$181<=$B$2))),1),"") | J5: =IF(I5="","",SUMIFS('기록'!$G:$G,'기록'!$C:$C,I5,'기록'!$A:$A,">="&$B$1,'기록'!$A:$A,"<="&$B$2)) | K5: =IF(I5="","",COUNTA(_xlfn.UNIQUE(_xlfn.FILTER('기록'!$A:$A,(('기록'!$C:$C=I5)*('기록'!$A:$A>=$B$1)*('기록'!$A:$A<=$B$2)))))) | L5: =IF(I5="","",J5) | N5: =_xlfn.SORTBY(H5:L204,L5:L204,-1)
A6: =IFERROR(INDEX($N$5:$Q$204,2,1),"") | B6: =IFERROR(INDEX($N$5:$Q$204,2,2),"") | C6: =IFERROR(INDEX($N$5:$Q$204,2,3),"") | D6: =IFERROR(INDEX($N$5:$Q$204,2,4),"") | H6: =IF(I6="","",2) | I6: =IFERROR(INDEX(_xlfn.UNIQUE(_xlfn.FILTER('기록'!$C$2:$C$181,('기록'!$C$2:$C$181<>"")*('기록'!$A$2:$A$181>=$B$1)*('기록'!$A$2:$A$181<=$B$2))),2),"") | J6: =IF(I6="","",SUMIFS('기록'!$G:$G,'기록'!$C:$C,I6,'기록'!$A:$A,">="&$B$1,'기록'!$A:$A,"<="&$B$2)) | K6: =IF(I6="","",COUNTA(_xlfn.UNIQUE(_xlfn.FILTER('기록'!$A:$A,(('기록'!$C:$C=I6)*('기록'!$A:$A>=$B$1)*('기록'!$A:$A<=$B$2)))))) | L6: =IF(I6="","",J6)
A7: =IFERROR(INDEX($N$5:$Q$204,3,1),"") | B7: =IFERROR(INDEX($N$5:$Q$204,3,2),"") | C7: =IFERROR(INDEX($N$5:$Q$204,3,3),"") | D7: =IFERROR(INDEX($N$5:$Q$204,3,4),"") | H7: =IF(I7="","",3) | I7: =IFERROR(INDEX(_xlfn.UNIQUE(_xlfn.FILTER('기록'!$C$2:$C$181,('기록'!$C$2:$C$181<>"")*('기록'!$A$2:$A$181>=$B$1)*('기록'!$A$2:$A$181<=$B$2))),3),"") | J7: =IF(I7="","",SUMIFS('기록'!$G:$G,'기록'!$C:$C,I7,'기록'!$A:$A,">="&$B$1,'기록'!$A:$A,"<="&$B$2)) | K7: =IF(I7="","",COUNTA(_xlfn.UNIQUE(_xlfn.FILTER('기록'!$A:$A,(('기록'!$C:$C=I7)*('기록'!$A:$A>=$B$1)*('기록'!$A:$A<=$B$2)))))) | L7: =IF(I7="","",J7)
A8: =IFERROR(INDEX($N$5:$Q$204,4,1),"") | B8: =IFERROR(INDEX($N$5:$Q$204,4,2),"") | C8: =IFERROR(INDEX($N$5:$Q$204,4,3),"") | D8: =IFERROR(INDEX($N$5:$Q$204,4,4),"") | H8: =IF(I8="","",4) | I8: =IFERROR(INDEX(_xlfn.UNIQUE(_xlfn.FILTER('기록'!$C$2:$C$181,('기록'!$C$2:$C$181<>"")*('기록'!$A$2:$A$181>=$B$1)*('기록'!$A$2:$A$181<=$B$2))),4),"") | J8: =IF(I8="","",SUMIFS('기록'!$G:$G,'기록'!$C:$C,I8,'기록'!$A:$A,">="&$B$1,'기록'!$A:$A,"<="&$B$2)) | K8: =IF(I8="","",COUNTA(_xlfn.UNIQUE(_xlfn.FILTER('기록'!$A:$A,(('기록'!$C:$C=I8)*('기록'!$A:$A>=$B$1)*('기록'!$A:$A<=$B$2)))))) | L8: =IF(I8="","",J8)
A9: =IFERROR(INDEX($N$5:$Q$204,5,1),"") | B9: =IFERROR(INDEX($N$5:$Q$204,5,2),"") | C9: =IFERROR(INDEX($N$5:$Q$204,5,3),"") | D9: =IFERROR(INDEX($N$5:$Q$204,5,4),"") | H9: =IF(I9="","",5) | I9: =IFERROR(INDEX(_xlfn.UNIQUE(_xlfn.FILTER('기록'!$C$2:$C$181,('기록'!$C$2:$C$181<>"")*('기록'!$A$2:$A$181>=$B$1)*('기록'!$A$2:$A$181<=$B$2))),5),"") | J9: =IF(I9="","",SUMIFS('기록'!$G:$G,'기록'!$C:$C,I9,'기록'!$A:$A,">="&$B$1,'기록'!$A:$A,"<="&$B$2)) | K9: =IF(I9="","",COUNTA(_xlfn.UNIQUE(_xlfn.FILTER('기록'!$A:$A,(('기록'!$C:$C=I9)*('기록'!$A:$A>=$B$1)*('기록'!$A:$A<=$B$2)))))) | L9: =IF(I9="","",J9)
A10: =IFERROR(INDEX($N$5:$Q$204,6,1),"") | B10: =IFERROR(INDEX($N$5:$Q$204,6,2),"") | C10: =IFERROR(INDEX($N$5:$Q$204,6,3),"") | D10: =IFERROR(INDEX($N$5:$Q$204,6,4),"") | H10: =IF(I10="","",6) | I10: =IFERROR(INDEX(_xlfn.UNIQUE(_xlfn.FILTER('기록'!$C$2:$C$181,('기록'!$C$2:$C$181<>"")*('기록'!$A$2:$A$181>=$B$1)*('기록'!$A$2:$A$181<=$B$2))),6),"") | J10: =IF(I10="","",SUMIFS('기록'!$G:$G,'기록'!$C:$C,I10,'기록'!$A:$A,">="&$B$1,'기록'!$A:$A,"<="&$B$2)) | K10: =IF(I10="","",COUNTA(_xlfn.UNIQUE(_xlfn.FILTER('기록'!$A:$A,(('기록'!$C:$C=I10)*('기록'!$A:$A>=$B$1)*('기록'!$A:$A<=$B$2)))))) | L10: =IF(I10="","",J10)
A11: =IFERROR(INDEX($N$5:$Q$204,7,1),"") | B11: =IFERROR(INDEX($N$5:$Q$204,7,2),"") | C11: =IFERROR(INDEX($N$5:$Q$204,7,3),"") | D11: =IFERROR(INDEX($N$5:$Q$204,7,4),"") | H11: =IF(I11="","",7) | I11: =IFERROR(INDEX(_xlfn.UNIQUE(_xlfn.FILTER('기록'!$C$2:$C$181,('기록'!$C$2:$C$181<>"")*('기록'!$A$2:$A$181>=$B$1)*('기록'!$A$2:$A$181<=$B$2))),7),"") | J11: =IF(I11="","",SUMIFS('기록'!$G:$G,'기록'!$C:$C,I11,'기록'!$A:$A,">="&$B$1,'기록'!$A:$A,"<="&$B$2)) | K11: =IF(I11="","",COUNTA(_xlfn.UNIQUE(_xlfn.FILTER('기록'!$A:$A,(('기록'!$C:$C=I11)*('기록'!$A:$A>=$B$1)*('기록'!$A:$A<=$B$2)))))) | L11: =IF(I11="","",J11)
A12: =IFERROR(INDEX($N$5:$Q$204,8,1),"") | B12: =IFERROR(INDEX($N$5:$Q$204,8,2),"") | C12: =IFERROR(INDEX($N$5:$Q$204,8,3),"") | D12: =IFERROR(INDEX($N$5:$Q$204,8,4),"") | H12: =IF(I12="","",8) | I12: =IFERROR(INDEX(_xlfn.UNIQUE(_xlfn.FILTER('기록'!$C$2:$C$181,('기록'!$C$2:$C$181<>"")*('기록'!$A$2:$A$181>=$B$1)*('기록'!$A$2:$A$181<=$B$2))),8),"") | J12: =IF(I12="","",SUMIFS('기록'!$G:$G,'기록'!$C:$C,I12,'기록'!$A:$A,">="&$B$1,'기록'!$A:$A,"<="&$B$2)) | K12: =IF(I12="","",COUNTA(_xlfn.UNIQUE(_xlfn.FILTER('기록'!$A:$A,(('기록'!$C:$C=I12)*('기록'!$A:$A>=$B$1)*('기록'!$A:$A<=$B$2)))))) | L12: =IF(I12="","",J12)
A13: =IFERROR(INDEX($N$5:$Q$204,9,1),"") | B13: =IFERROR(INDEX($N$5:$Q$204,9,2),"") | C13: =IFERROR(INDEX($N$5:$Q$204,9,3),"") | D13: =IFERROR(INDEX($N$5:$Q$204,9,4),"") | H13: =IF(I13="","",9) | I13: =IFERROR(INDEX(_xlfn.UNIQUE(_xlfn.FILTER('기록'!$C$2:$C$181,('기록'!$C$2:$C$181<>"")*('기록'!$A$2:$A$181>=$B$1)*('기록'!$A$2:$A$181<=$B$2))),9),"") | J13: =IF(I13="","",SUMIFS('기록'!$G:$G,'기록'!$C:$C,I13,'기록'!$A:$A,">="&$B$1,'기록'!$A:$A,"<="&$B$2)) | K13: =IF(I13="","",COUNTA(_xlfn.UNIQUE(_xlfn.FILTER('기록'!$A:$A,(('기록'!$C:$C=I13)*('기록'!$A:$A>=$B$1)*('기록'!$A:$A<=$B$2)))))) | L13: =IF(I13="","",J13)
A14: =IFERROR(INDEX($N$5:$Q$204,10,1),"") | B14: =IFERROR(INDEX($N$5:$Q$204,10,2),"") | C14: =IFERROR(INDEX($N$5:$Q$204,10,3),"") | D14: =IFERROR(INDEX($N$5:$Q$204,10,4),"") | H14: =IF(I14="","",10) | I14: =IFERROR(INDEX(_xlfn.UNIQUE(_xlfn.FILTER('기록'!$C$2:$C$181,('기록'!$C$2:$C$181<>"")*('기록'!$A$2:$A$181>=$B$1)*('기록'!$A$2:$A$181<=$B$2))),10),"") | J14: =IF(I14="","",SUMIFS('기록'!$G:$G,'기록'!$C:$C,I14,'기록'!$A:$A,">="&$B$1,'기록'!$A:$A,"<="&$B$2)) | K14: =IF(I14="","",COUNTA(_xlfn.UNIQUE(_xlfn.FILTER('기록'!$A:$A,(('기록'!$C:$C=I14)*('기록'!$A:$A>=$B$1)*('기록'!$A:$A<=$B$2)))))) | L14: =IF(I14="","",J14)
A15: =IFERROR(INDEX($N$5:$Q$204,11,1),"") | B15: =IFERROR(INDEX($N$5:$Q$204,11,2),"") | C15: =IFERROR(INDEX($N$5:$Q$204,11,3),"") | D15: =IFERROR(INDEX($N$5:$Q$204,11,4),"") | H15: =IF(I15="","",11) | I15: =IFERROR(INDEX(_xlfn.UNIQUE(_xlfn.FILTER('기록'!$C$2:$C$181,('기록'!$C$2:$C$181<>"")*('기록'!$A$2:$A$181>=$B$1)*('기록'!$A$2:$A$181<=$B$2))),11),"") | J15: =IF(I15="","",SUMIFS('기록'!$G:$G,'기록'!$C:$C,I15,'기록'!$A:$A,">="&$B$1,'기록'!$A:$A,"<="&$B$2)) | K15: =IF(I15="","",COUNTA(_xlfn.UNIQUE(_xlfn.FILTER('기록'!$A:$A,(('기록'!$C:$C=I15)*('기록'!$A:$A>=$B$1)*('기록'!$A:$A<=$B$2)))))) | L15: =IF(I15="","",J15)
A16: =IFERROR(INDEX($N$5:$Q$204,12,1),"") | B16: =IFERROR(INDEX($N$5:$Q$204,12,2),"") | C16: =IFERROR(INDEX($N$5:$Q$204,12,3),"") | D16: =IFERROR(INDEX($N$5:$Q$204,12,4),"") | H16: =IF(I16="","",12) | I16: =IFERROR(INDEX(_xlfn.UNIQUE(_xlfn.FILTER('기록'!$C$2:$C$181,('기록'!$C$2:$C$181<>"")*('기록'!$A$2:$A$181>=$B$1)*('기록'!$A$2:$A$181<=$B$2))),12),"") | J16: =IF(I16="","",SUMIFS('기록'!$G:$G,'기록'!$C:$C,I16,'기록'!$A:$A,">="&$B$1,'기록'!$A:$A,"<="&$B$2)) | K16: =IF(I16="","",COUNTA(_xlfn.UNIQUE(_xlfn.FILTER('기록'!$A:$A,(('기록'!$C:$C=I16)*('기록'!$A:$A>=$B$1)*('기록'!$A:$A<=$B$2)))))) | L16: =IF(I16="","",J16)
A17: =IFERROR(INDEX($N$5:$Q$204,13,1),"") | B17: =IFERROR(INDEX($N$5:$Q$204,13,2),"") | C17: =IFERROR(INDEX($N$5:$Q$204,13,3),"") | D17: =IFERROR(INDEX($N$5:$Q$204,13,4),"") | H17: =IF(I17="","",13) | I17: =IFERROR(INDEX(_xlfn.UNIQUE(_xlfn.FILTER('기록'!$C$2:$C$181,('기록'!$C$2:$C$181<>"")*('기록'!$A$2:$A$181>=$B$1)*('기록'!$A$2:$A$181<=$B$2))),13),"") | J17: =IF(I17="","",SUMIFS('기록'!$G:$G,'기록'!$C:$C,I17,'기록'!$A:$A,">="&$B$1,'기록'!$A:$A,"<="&$B$2)) | K17: =IF(I17="","",COUNTA(_xlfn.UNIQUE(_xlfn.FILTER('기록'!$A:$A,(('기록'!$C:$C=I17)*('기록'!$A:$A>=$B$1)*('기록'!$A:$A<=$B$2)))))) | L17: =IF(I17="","",J17)
A18: =IFERROR(INDEX($N$5:$Q$204,14,1),"") | B18: =IFERROR(INDEX($N$5:$Q$204,14,2),"") | C18: =IFERROR(INDEX($N$5:$Q$204,14,3),"") | D18: =IFERROR(INDEX($N$5:$Q$204,14,4),"") | H18: =IF(I18="","",14) | I18: =IFERROR(INDEX(_xlfn.UNIQUE(_xlfn.FILTER('기록'!$C$2:$C$181,('기록'!$C$2:$C$181<>"")*('기록'!$A$2:$A$181>=$B$1)*('기록'!$A$2:$A$181<=$B$2))),14),"") | J18: =IF(I18="","",SUMIFS('기록'!$G:$G,'기록'!$C:$C,I18,'기록'!$A:$A,">="&$B$1,'기록'!$A:$A,"<="&$B$2)) | K18: =IF(I18="","",COUNTA(_xlfn.UNIQUE(_xlfn.FILTER('기록'!$A:$A,(('기록'!$C:$C=I18)*('기록'!$A:$A>=$B$1)*('기록'!$A:$A<=$B$2)))))) | L18: =IF(I18="","",J18)
A19: =IFERROR(INDEX($N$5:$Q$204,15,1),"") | B19: =IFERROR(INDEX($N$5:$Q$204,15,2),"") | C19: =IFERROR(INDEX($N$5:$Q$204,15,3),"") | D19: =IFERROR(INDEX($N$5:$Q$204,15,4),"") | H19: =IF(I19="","",15) | I19: =IFERROR(INDEX(_xlfn.UNIQUE(_xlfn.FILTER('기록'!$C$2:$C$181,('기록'!$C$2:$C$181<>"")*('기록'!$A$2:$A$181>=$B$1)*('기록'!$A$2:$A$181<=$B$2))),15),"") | J19: =IF(I19="","",SUMIFS('기록'!$G:$G,'기록'!$C:$C,I19,'기록'!$A:$A,">="&$B$1,'기록'!$A:$A,"<="&$B$2)) | K19: =IF(I19="","",COUNTA(_xlfn.UNIQUE(_xlfn.FILTER('기록'!$A:$A,(('기록'!$C:$C=I19)*('기록'!$A:$A>=$B$1)*('기록'!$A:$A<=$B$2)))))) | L19: =IF(I19="","",J19)
A20: =IFERROR(INDEX($N$5:$Q$204,16,1),"") | B20: =IFERROR(INDEX($N$5:$Q$204,16,2),"") | C20: =IFERROR(INDEX($N$5:$Q$204,16,3),"") | D20: =IFERROR(INDEX($N$5:$Q$204,16,4),"") | H20: =IF(I20="","",16) | I20: =IFERROR(INDEX(_xlfn.UNIQUE(_xlfn.FILTER('기록'!$C$2:$C$181,('기록'!$C$2:$C$181<>"")*('기록'!$A$2:$A$181>=$B$1)*('기록'!$A$2:$A$181<=$B$2))),16),"") | J20: =IF(I20="","",SUMIFS('기록'!$G:$G,'기록'!$C:$C,I20,'기록'!$A:$A,">="&$B$1,'기록'!$A:$A,"<="&$B$2)) | K20: =IF(I20="","",COUNTA(_xlfn.UNIQUE(_xlfn.FILTER('기록'!$A:$A,(('기록'!$C:$C=I20)*('기록'!$A:$A>=$B$1)*('기록'!$A:$A<=$B$2)))))) | L20: =IF(I20="","",J20)
A21: =IFERROR(INDEX($N$5:$Q$204,17,1),"") | B21: =IFERROR(INDEX($N$5:$Q$204,17,2),"") | C21: =IFERROR(INDEX($N$5:$Q$204,17,3),"") | D21: =IFERROR(INDEX($N$5:$Q$204,17,4),"") | H21: =IF(I21="","",17) | I21: =IFERROR(INDEX(_xlfn.UNIQUE(_xlfn.FILTER('기록'!$C$2:$C$181,('기록'!$C$2:$C$181<>"")*('기록'!$A$2:$A$181>=$B$1)*('기록'!$A$2:$A$181<=$B$2))),17),"") | J21: =IF(I21="","",SUMIFS('기록'!$G:$G,'기록'!$C:$C,I21,'기록'!$A:$A,">="&$B$1,'기록'!$A:$A,"<="&$B$2)) | K21: =IF(I21="","",COUNTA(_xlfn.UNIQUE(_xlfn.FILTER('기록'!$A:$A,(('기록'!$C:$C=I21)*('기록'!$A:$A>=$B$1)*('기록'!$A:$A<=$B$2)))))) | L21: =IF(I21="","",J21)
A22: =IFERROR(INDEX($N$5:$Q$204,18,1),"") | B22: =IFERROR(INDEX($N$5:$Q$204,18,2),"") | C22: =IFERROR(INDEX($N$5:$Q$204,18,3),"") | D22: =IFERROR(INDEX($N$5:$Q$204,18,4),"") | H22: =IF(I22="","",18) | I22: =IFERROR(INDEX(_xlfn.UNIQUE(_xlfn.FILTER('기록'!$C$2:$C$181,('기록'!$C$2:$C$181<>"")*('기록'!$A$2:$A$181>=$B$1)*('기록'!$A$2:$A$181<=$B$2))),18),"") | J22: =IF(I22="","",SUMIFS('기록'!$G:$G,'기록'!$C:$C,I22,'기록'!$A:$A,">="&$B$1,'기록'!$A:$A,"<="&$B$2)) | K22: =IF(I22="","",COUNTA(_xlfn.UNIQUE(_xlfn.FILTER('기록'!$A:$A,(('기록'!$C:$C=I22)*('기록'!$A:$A>=$B$1)*('기록'!$A:$A<=$B$2)))))) | L22: =IF(I22="","",J22)
A23: =IFERROR(INDEX($N$5:$Q$204,19,1),"") | B23: =IFERROR(INDEX($N$5:$Q$204,19,2),"") | C23: =IFERROR(INDEX($N$5:$Q$204,19,3),"") | D23: =IFERROR(INDEX($N$5:$Q$204,19,4),"") | H23: =IF(I23="","",19) | I23: =IFERROR(INDEX(_xlfn.UNIQUE(_xlfn.FILTER('기록'!$C$2:$C$181,('기록'!$C$2:$C$181<>"")*('기록'!$A$2:$A$181>=$B$1)*('기록'!$A$2:$A$181<=$B$2))),19),"") | J23: =IF(I23="","",SUMIFS('기록'!$G:$G,'기록'!$C:$C,I23,'기록'!$A:$A,">="&$B$1,'기록'!$A:$A,"<="&$B$2)) | K23: =IF(I23="","",COUNTA(_xlfn.UNIQUE(_xlfn.FILTER('기록'!$A:$A,(('기록'!$C:$C=I23)*('기록'!$A:$A>=$B$1)*('기록'!$A:$A<=$B$2)))))) | L23: =IF(I23="","",J23)
A24: =IFERROR(INDEX($N$5:$Q$204,20,1),"") | B24: =IFERROR(INDEX($N$5:$Q$204,20,2),"") | C24: =IFERROR(INDEX($N$5:$Q$204,20,3),"") | D24: =IFERROR(INDEX($N$5:$Q$204,20,4),"") | H24: =IF(I24="","",20) | I24: =IFERROR(INDEX(_xlfn.UNIQUE(_xlfn.FILTER('기록'!$C$2:$C$181,('기록'!$C$2:$C$181<>"")*('기록'!$A$2:$A$181>=$B$1)*('기록'!$A$2:$A$181<=$B$2))),20),"") | J24: =IF(I24="","",SUMIFS('기록'!$G:$G,'기록'!$C:$C,I24,'기록'!$A:$A,">="&$B$1,'기록'!$A:$A,"<="&$B$2)) | K24: =IF(I24="","",COUNTA(_xlfn.UNIQUE(_xlfn.FILTER('기록'!$A:$A,(('기록'!$C:$C=I24)*('기록'!$A:$A>=$B$1)*('기록'!$A:$A<=$B$2)))))) | L24: =IF(I24="","",J24)
A25: =IFERROR(INDEX($N$5:$Q$204,21,1),"") | B25: =IFERROR(INDEX($N$5:$Q$204,21,2),"") | C25: =IFERROR(INDEX($N$5:$Q$204,21,3),"") | D25: =IFERROR(INDEX($N$5:$Q$204,21,4),"") | H25: =IF(I25="","",21) | I25: =IFERROR(INDEX(_xlfn.UNIQUE(_xlfn.FILTER('기록'!$C$2:$C$181,('기록'!$C$2:$C$181<>"")*('기록'!$A$2:$A$181>=$B$1)*('기록'!$A$2:$A$181<=$B$2))),21),"") | J25: =IF(I25="","",SUMIFS('기록'!$G:$G,'기록'!$C:$C,I25,'기록'!$A:$A,">="&$B$1,'기록'!$A:$A,"<="&$B$2)) | K25: =IF(I25="","",COUNTA(_xlfn.UNIQUE(_xlfn.FILTER('기록'!$A:$A,(('기록'!$C:$C=I25)*('기록'!$A:$A>=$B$1)*('기록'!$A:$A<=$B$2)))))) | L25: =IF(I25="","",J25)
A26: =IFERROR(INDEX($N$5:$Q$204,22,1),"") | B26: =IFERROR(INDEX($N$5:$Q$204,22,2),"") | C26: =IFERROR(INDEX($N$5:$Q$204,22,3),"") | D26: =IFERROR(INDEX($N$5:$Q$204,22,4),"") | H26: =IF(I26="","",22) | I26: =IFERROR(INDEX(_xlfn.UNIQUE(_xlfn.FILTER('기록'!$C$2:$C$181,('기록'!$C$2:$C$181<>"")*('기록'!$A$2:$A$181>=$B$1)*('기록'!$A$2:$A$181<=$B$2))),22),"") | J26: =IF(I26="","",SUMIFS('기록'!$G:$G,'기록'!$C:$C,I26,'기록'!$A:$A,">="&$B$1,'기록'!$A:$A,"<="&$B$2)) | K26: =IF(I26="","",COUNTA(_xlfn.UNIQUE(_xlfn.FILTER('기록'!$A:$A,(('기록'!$C:$C=I26)*('기록'!$A:$A>=$B$1)*('기록'!$A:$A<=$B$2)))))) | L26: =IF(I26="","",J26)
A27: =IFERROR(INDEX($N$5:$Q$204,23,1),"") | B27: =IFERROR(INDEX($N$5:$Q$204,23,2),"") | C27: =IFERROR(INDEX($N$5:$Q$204,23,3),"") | D27: =IFERROR(INDEX($N$5:$Q$204,23,4),"") | H27: =IF(I27="","",23) | I27: =IFERROR(INDEX(_xlfn.UNIQUE(_xlfn.FILTER('기록'!$C$2:$C$181,('기록'!$C$2:$C$181<>"")*('기록'!$A$2:$A$181>=$B$1)*('기록'!$A$2:$A$181<=$B$2))),23),"") | J27: =IF(I27="","",SUMIFS('기록'!$G:$G,'기록'!$C:$C,I27,'기록'!$A:$A,">="&$B$1,'기록'!$A:$A,"<="&$B$2)) | K27: =IF(I27="","",COUNTA(_xlfn.UNIQUE(_xlfn.FILTER('기록'!$A:$A,(('기록'!$C:$C=I27)*('기록'!$A:$A>=$B$1)*('기록'!$A:$A<=$B$2)))))) | L27: =IF(I27="","",J27)
A28: =IFERROR(INDEX($N$5:$Q$204,24,1),"") | B28: =IFERROR(INDEX($N$5:$Q$204,24,2),"") | C28: =IFERROR(INDEX($N$5:$Q$204,24,3),"") | D28: =IFERROR(INDEX($N$5:$Q$204,24,4),"") | H28: =IF(I28="","",24) | I28: =IFERROR(INDEX(_xlfn.UNIQUE(_xlfn.FILTER('기록'!$C$2:$C$181,('기록'!$C$2:$C$181<>"")*('기록'!$A$2:$A$181>=$B$1)*('기록'!$A$2:$A$181<=$B$2))),24),"") | J28: =IF(I28="","",SUMIFS('기록'!$G:$G,'기록'!$C:$C,I28,'기록'!$A:$A,">="&$B$1,'기록'!$A:$A,"<="&$B$2)) | K28: =IF(I28="","",COUNTA(_xlfn.UNIQUE(_xlfn.FILTER('기록'!$A:$A,(('기록'!$C:$C=I28)*('기록'!$A:$A>=$B$1)*('기록'!$A:$A<=$B$2)))))) | L28: =IF(I28="","",J28)
A29: =IFERROR(INDEX($N$5:$Q$204,25,1),"") | B29: =IFERROR(INDEX($N$5:$Q$204,25,2),"") | C29: =IFERROR(INDEX($N$5:$Q$204,25,3),"") | D29: =IFERROR(INDEX($N$5:$Q$204,25,4),"") | H29: =IF(I29="","",25) | I29: =IFERROR(INDEX(_xlfn.UNIQUE(_xlfn.FILTER('기록'!$C$2:$C$181,('기록'!$C$2:$C$181<>"")*('기록'!$A$2:$A$181>=$B$1)*('기록'!$A$2:$A$181<=$B$2))),25),"") | J29: =IF(I29="","",SUMIFS('기록'!$G:$G,'기록'!$C:$C,I29,'기록'!$A:$A,">="&$B$1,'기록'!$A:$A,"<="&$B$2)) | K29: =IF(I29="","",COUNTA(_xlfn.UNIQUE(_xlfn.FILTER('기록'!$A:$A,(('기록'!$C:$C=I29)*('기록'!$A:$A>=$B$1)*('기록'!$A:$A<=$B$2)))))) | L29: =IF(I29="","",J29)
A30: =IFERROR(INDEX($N$5:$Q$204,26,1),"") | B30: =IFERROR(INDEX($N$5:$Q$204,26,2),"") | C30: =IFERROR(INDEX($N$5:$Q$204,26,3),"") | D30: =IFERROR(INDEX($N$5:$Q$204,26,4),"") | H30: =IF(I30="","",26) | I30: =IFERROR(INDEX(_xlfn.UNIQUE(_xlfn.FILTER('기록'!$C$2:$C$181,('기록'!$C$2:$C$181<>"")*('기록'!$A$2:$A$181>=$B$1)*('기록'!$A$2:$A$181<=$B$2))),26),"") | J30: =IF(I30="","",SUMIFS('기록'!$G:$G,'기록'!$C:$C,I30,'기록'!$A:$A,">="&$B$1,'기록'!$A:$A,"<="&$B$2)) | K30: =IF(I30="","",COUNTA(_xlfn.UNIQUE(_xlfn.FILTER('기록'!$A:$A,(('기록'!$C:$C=I30)*('기록'!$A:$A>=$B$1)*('기록'!$A:$A<=$B$2)))))) | L30: =IF(I30="","",J30)
A31: =IFERROR(INDEX($N$5:$Q$204,27,1),"") | B31: =IFERROR(INDEX($N$5:$Q$204,27,2),"") | C31: =IFERROR(INDEX($N$5:$Q$204,27,3),"") | D31: =IFERROR(INDEX($N$5:$Q$204,27,4),"") | H31: =IF(I31="","",27) | I31: =IFERROR(INDEX(_xlfn.UNIQUE(_xlfn.FILTER('기록'!$C$2:$C$181,('기록'!$C$2:$C$181<>"")*('기록'!$A$2:$A$181>=$B$1)*('기록'!$A$2:$A$181<=$B$2))),27),"") | J31: =IF(I31="","",SUMIFS('기록'!$G:$G,'기록'!$C:$C,I31,'기록'!$A:$A,">="&$B$1,'기록'!$A:$A,"<="&$B$2)) | K31: =IF(I31="","",COUNTA(_xlfn.UNIQUE(_xlfn.FILTER('기록'!$A:$A,(('기록'!$C:$C=I31)*('기록'!$A:$A>=$B$1)*('기록'!$A:$A<=$B$2)))))) | L31: =IF(I31="","",J31)
A32: =IFERROR(INDEX($N$5:$Q$204,28,1),"") | B32: =IFERROR(INDEX($N$5:$Q$204,28,2),"") | C32: =IFERROR(INDEX($N$5:$Q$204,28,3),"") | D32: =IFERROR(INDEX($N$5:$Q$204,28,4),"") | H32: =IF(I32="","",28) | I32: =IFERROR(INDEX(_xlfn.UNIQUE(_xlfn.FILTER('기록'!$C$2:$C$181,('기록'!$C$2:$C$181<>"")*('기록'!$A$2:$A$181>=$B$1)*('기록'!$A$2:$A$181<=$B$2))),28),"") | J32: =IF(I32="","",SUMIFS('기록'!$G:$G,'기록'!$C:$C,I32,'기록'!$A:$A,">="&$B$1,'기록'!$A:$A,"<="&$B$2)) | K32: =IF(I32="","",COUNTA(_xlfn.UNIQUE(_xlfn.FILTER('기록'!$A:$A,(('기록'!$C:$C=I32)*('기록'!$A:$A>=$B$1)*('기록'!$A:$A<=$B$2)))))) | L32: =IF(I32="","",J32)
A33: =IFERROR(INDEX($N$5:$Q$204,29,1),"") | B33: =IFERROR(INDEX($N$5:$Q$204,29,2),"") | C33: =IFERROR(INDEX($N$5:$Q$204,29,3),"") | D33: =IFERROR(INDEX($N$5:$Q$204,29,4),"") | H33: =IF(I33="","",29) | I33: =IFERROR(INDEX(_xlfn.UNIQUE(_xlfn.FILTER('기록'!$C$2:$C$181,('기록'!$C$2:$C$181<>"")*('기록'!$A$2:$A$181>=$B$1)*('기록'!$A$2:$A$181<=$B$2))),29),"") | J33: =IF(I33="","",SUMIFS('기록'!$G:$G,'기록'!$C:$C,I33,'기록'!$A:$A,">="&$B$1,'기록'!$A:$A,"<="&$B$2)) | K33: =IF(I33="","",COUNTA(_xlfn.UNIQUE(_xlfn.FILTER('기록'!$A:$A,(('기록'!$C:$C=I33)*('기록'!$A:$A>=$B$1)*('기록'!$A:$A<=$B$2)))))) | L33: =IF(I33="","",J33)
A34: =IFERROR(INDEX($N$5:$Q$204,30,1),"") | B34: =IFERROR(INDEX($N$5:$Q$204,30,2),"") | C34: =IFERROR(INDEX($N$5:$Q$204,30,3),"") | D34: =IFERROR(INDEX($N$5:$Q$204,30,4),"") | H34: =IF(I34="","",30) | I34: =IFERROR(INDEX(_xlfn.UNIQUE(_xlfn.FILTER('기록'!$C$2:$C$181,('기록'!$C$2:$C$181<>"")*('기록'!$A$2:$A$181>=$B$1)*('기록'!$A$2:$A$181<=$B$2))),30),"") | J34: =IF(I34="","",SUMIFS('기록'!$G:$G,'기록'!$C:$C,I34,'기록'!$A:$A,">="&$B$1,'기록'!$A:$A,"<="&$B$2)) | K34: =IF(I34="","",COUNTA(_xlfn.UNIQUE(_xlfn.FILTER('기록'!$A:$A,(('기록'!$C:$C=I34)*('기록'!$A:$A>=$B$1)*('기록'!$A:$A<=$B$2)))))) | L34: =IF(I34="","",J34)
A35: =IFERROR(INDEX($N$5:$Q$204,31,1),"") | B35: =IFERROR(INDEX($N$5:$Q$204,31,2),"") | C35: =IFERROR(INDEX($N$5:$Q$204,31,3),"") | D35: =IFERROR(INDEX($N$5:$Q$204,31,4),"") | H35: =IF(I35="","",31) | I35: =IFERROR(INDEX(_xlfn.UNIQUE(_xlfn.FILTER('기록'!$C$2:$C$181,('기록'!$C$2:$C$181<>"")*('기록'!$A$2:$A$181>=$B$1)*('기록'!$A$2:$A$181<=$B$2))),31),"") | J35: =IF(I35="","",SUMIFS('기록'!$G:$G,'기록'!$C:$C,I35,'기록'!$A:$A,">="&$B$1,'기록'!$A:$A,"<="&$B$2)) | K35: =IF(I35="","",COUNTA(_xlfn.UNIQUE(_xlfn.FILTER('기록'!$A:$A,(('기록'!$C:$C=I35)*('기록'!$A:$A>=$B$1)*('기록'!$A:$A<=$B$2)))))) | L35: =IF(I35="","",J35)
A36: =IFERROR(INDEX($N$5:$Q$204,32,1),"") | B36: =IFERROR(INDEX($N$5:$Q$204,32,2),"") | C36: =IFERROR(INDEX($N$5:$Q$204,32,3),"") | D36: =IFERROR(INDEX($N$5:$Q$204,32,4),"") | H36: =IF(I36="","",32) | I36: =IFERROR(INDEX(_xlfn.UNIQUE(_xlfn.FILTER('기록'!$C$2:$C$181,('기록'!$C$2:$C$181<>"")*('기록'!$A$2:$A$181>=$B$1)*('기록'!$A$2:$A$181<=$B$2))),32),"") | J36: =IF(I36="","",SUMIFS('기록'!$G:$G,'기록'!$C:$C,I36,'기록'!$A:$A,">="&$B$1,'기록'!$A:$A,"<="&$B$2)) | K36: =IF(I36="","",COUNTA(_xlfn.UNIQUE(_xlfn.FILTER('기록'!$A:$A,(('기록'!$C:$C=I36)*('기록'!$A:$A>=$B$1)*('기록'!$A:$A<=$B$2)))))) | L36: =IF(I36="","",J36)
A37: =IFERROR(INDEX($N$5:$Q$204,33,1),"") | B37: =IFERROR(INDEX($N$5:$Q$204,33,2),"") | C37: =IFERROR(INDEX($N$5:$Q$204,33,3),"") | D37: =IFERROR(INDEX($N$5:$Q$204,33,4),"") | H37: =IF(I37="","",33) | I37: =IFERROR(INDEX(_xlfn.UNIQUE(_xlfn.FILTER('기록'!$C$2:$C$181,('기록'!$C$2:$C$181<>"")*('기록'!$A$2:$A$181>=$B$1)*('기록'!$A$2:$A$181<=$B$2))),33),"") | J37: =IF(I37="","",SUMIFS('기록'!$G:$G,'기록'!$C:$C,I37,'기록'!$A:$A,">="&$B$1,'기록'!$A:$A,"<="&$B$2)) | K37: =IF(I37="","",COUNTA(_xlfn.UNIQUE(_xlfn.FILTER('기록'!$A:$A,(('기록'!$C:$C=I37)*('기록'!$A:$A>=$B$1)*('기록'!$A:$A<=$B$2)))))) | L37: =IF(I37="","",J37)
A38: =IFERROR(INDEX($N$5:$Q$204,34,1),"") | B38: =IFERROR(INDEX($N$5:$Q$204,34,2),"") | C38: =IFERROR(INDEX($N$5:$Q$204,34,3),"") | D38: =IFERROR(INDEX($N$5:$Q$204,34,4),"") | H38: =IF(I38="","",34) | I38: =IFERROR(INDEX(_xlfn.UNIQUE(_xlfn.FILTER('기록'!$C$2:$C$181,('기록'!$C$2:$C$181<>"")*('기록'!$A$2:$A$181>=$B$1)*('기록'!$A$2:$A$181<=$B$2))),34),"") | J38: =IF(I38="","",SUMIFS('기록'!$G:$G,'기록'!$C:$C,I38,'기록'!$A:$A,">="&$B$1,'기록'!$A:$A,"<="&$B$2)) | K38: =IF(I38="","",COUNTA(_xlfn.UNIQUE(_xlfn.FILTER('기록'!$A:$A,(('기록'!$C:$C=I38)*('기록'!$A:$A>=$B$1)*('기록'!$A:$A<=$B$2)))))) | L38: =IF(I38="","",J38)
A39: =IFERROR(INDEX($N$5:$Q$204,35,1),"") | B39: =IFERROR(INDEX($N$5:$Q$204,35,2),"") | C39: =IFERROR(INDEX($N$5:$Q$204,35,3),"") | D39: =IFERROR(INDEX($N$5:$Q$204,35,4),"") | H39: =IF(I39="","",35) | I39: =IFERROR(INDEX(_xlfn.UNIQUE(_xlfn.FILTER('기록'!$C$2:$C$181,('기록'!$C$2:$C$181<>"")*('기록'!$A$2:$A$181>=$B$1)*('기록'!$A$2:$A$181<=$B$2))),35),"") | J39: =IF(I39="","",SUMIFS('기록'!$G:$G,'기록'!$C:$C,I39,'기록'!$A:$A,">="&$B$1,'기록'!$A:$A,"<="&$B$2)) | K39: =IF(I39="","",COUNTA(_xlfn.UNIQUE(_xlfn.FILTER('기록'!$A:$A,(('기록'!$C:$C=I39)*('기록'!$A:$A>=$B$1)*('기록'!$A:$A<=$B$2)))))) | L39: =IF(I39="","",J39)
A40: =IFERROR(INDEX($N$5:$Q$204,36,1),"") | B40: =IFERROR(INDEX($N$5:$Q$204,36,2),"") | C40: =IFERROR(INDEX($N$5:$Q$204,36,3),"") | D40: =IFERROR(INDEX($N$5:$Q$204,36,4),"") | H40: =IF(I40="","",36) | I40: =IFERROR(INDEX(_xlfn.UNIQUE(_xlfn.FILTER('기록'!$C$2:$C$181,('기록'!$C$2:$C$181<>"")*('기록'!$A$2:$A$181>=$B$1)*('기록'!$A$2:$A$181<=$B$2))),36),"") | J40: =IF(I40="","",SUMIFS('기록'!$G:$G,'기록'!$C:$C,I40,'기록'!$A:$A,">="&$B$1,'기록'!$A:$A,"<="&$B$2)) | K40: =IF(I40="","",COUNTA(_xlfn.UNIQUE(_xlfn.FILTER('기록'!$A:$A,(('기록'!$C:$C=I40)*('기록'!$A:$A>=$B$1)*('기록'!$A:$A<=$B$2)))))) | L40: =IF(I40="","",J40)
...

Sheet 출석
A1: 기간 시작 | B1: ='승점순위'!B1
A2: 기간 종료 | B2: ='승점순위'!B2
A3: 방문=날짜 수 · 게임=기록 행 수 · 방문 많은 순
A4: 닉네임 | B4: 방문 | C4: 게임 | D4: 방문 날짜
A5: =IFERROR(INDEX($N$5:$Q$204,1,1),"") | B5: =IFERROR(INDEX($N$5:$Q$204,1,2),"") | C5: =IFERROR(INDEX($N$5:$Q$204,1,3),"") | D5: =IFERROR(INDEX($N$5:$Q$204,1,4),"") | H5: =IFERROR(INDEX(_xlfn.UNIQUE(_xlfn.FILTER('기록'!$C$2:$C$181,('기록'!$C$2:$C$181<>"")*('기록'!$A$2:$A$181>=$B$1)*('기록'!$A$2:$A$181<=$B$2))),1),"") | I5: =IF(H5="","",COUNTA(_xlfn.UNIQUE(_xlfn.FILTER('기록'!$A:$A,(('기록'!$C:$C=H5)*('기록'!$A:$A>=$B$1)*('기록'!$A:$A<=$B$2)))))) | J5: =IF(H5="","",COUNTIFS('기록'!$C:$C,H5,'기록'!$A:$A,">="&$B$1,'기록'!$A:$A,"<="&$B$2)) | K5: =IF(H5="","",_xlfn.TEXTJOIN(", ",TRUE,_xlfn.UNIQUE(_xlfn.FILTER('기록'!$A:$A,(('기록'!$C:$C=H5)*('기록'!$A:$A>=$B$1)*('기록'!$A:$A<=$B$2)))))) | L5: =IF(H5="","",I5) | N5: =_xlfn.SORTBY(H5:L204,I5:I204,-1)
A6: =IFERROR(INDEX($N$5:$Q$204,2,1),"") | B6: =IFERROR(INDEX($N$5:$Q$204,2,2),"") | C6: =IFERROR(INDEX($N$5:$Q$204,2,3),"") | D6: =IFERROR(INDEX($N$5:$Q$204,2,4),"") | H6: =IFERROR(INDEX(_xlfn.UNIQUE(_xlfn.FILTER('기록'!$C$2:$C$181,('기록'!$C$2:$C$181<>"")*('기록'!$A$2:$A$181>=$B$1)*('기록'!$A$2:$A$181<=$B$2))),2),"") | I6: =IF(H6="","",COUNTA(_xlfn.UNIQUE(_xlfn.FILTER('기록'!$A:$A,(('기록'!$C:$C=H6)*('기록'!$A:$A>=$B$1)*('기록'!$A:$A<=$B$2)))))) | J6: =IF(H6="","",COUNTIFS('기록'!$C:$C,H6,'기록'!$A:$A,">="&$B$1,'기록'!$A:$A,"<="&$B$2)) | K6: =IF(H6="","",_xlfn.TEXTJOIN(", ",TRUE,_xlfn.UNIQUE(_xlfn.FILTER('기록'!$A:$A,(('기록'!$C:$C=H6)*('기록'!$A:$A>=$B$1)*('기록'!$A:$A<=$B$2)))))) | L6: =IF(H6="","",I6)
A7: =IFERROR(INDEX($N$5:$Q$204,3,1),"") | B7: =IFERROR(INDEX($N$5:$Q$204,3,2),"") | C7: =IFERROR(INDEX($N$5:$Q$204,3,3),"") | D7: =IFERROR(INDEX($N$5:$Q$204,3,4),"") | H7: =IFERROR(INDEX(_xlfn.UNIQUE(_xlfn.FILTER('기록'!$C$2:$C$181,('기록'!$C$2:$C$181<>"")*('기록'!$A$2:$A$181>=$B$1)*('기록'!$A$2:$A$181<=$B$2))),3),"") | I7: =IF(H7="","",COUNTA(_xlfn.UNIQUE(_xlfn.FILTER('기록'!$A:$A,(('기록'!$C:$C=H7)*('기록'!$A:$A>=$B$1)*('기록'!$A:$A<=$B$2)))))) | J7: =IF(H7="","",COUNTIFS('기록'!$C:$C,H7,'기록'!$A:$A,">="&$B$1,'기록'!$A:$A,"<="&$B$2)) | K7: =IF(H7="","",_xlfn.TEXTJOIN(", ",TRUE,_xlfn.UNIQUE(_xlfn.FILTER('기록'!$A:$A,(('기록'!$C:$C=H7)*('기록'!$A:$A>=$B$1)*('기록'!$A:$A<=$B$2)))))) | L7: =IF(H7="","",I7)
A8: =IFERROR(INDEX($N$5:$Q$204,4,1),"") | B8: =IFERROR(INDEX($N$5:$Q$204,4,2),"") | C8: =IFERROR(INDEX($N$5:$Q$204,4,3),"") | D8: =IFERROR(INDEX($N$5:$Q$204,4,4),"") | H8: =IFERROR(INDEX(_xlfn.UNIQUE(_xlfn.FILTER('기록'!$C$2:$C$181,('기록'!$C$2:$C$181<>"")*('기록'!$A$2:$A$181>=$B$1)*('기록'!$A$2:$A$181<=$B$2))),4),"") | I8: =IF(H8="","",COUNTA(_xlfn.UNIQUE(_xlfn.FILTER('기록'!$A:$A,(('기록'!$C:$C=H8)*('기록'!$A:$A>=$B$1)*('기록'!$A:$A<=$B$2)))))) | J8: =IF(H8="","",COUNTIFS('기록'!$C:$C,H8,'기록'!$A:$A,">="&$B$1,'기록'!$A:$A,"<="&$B$2)) | K8: =IF(H8="","",_xlfn.TEXTJOIN(", ",TRUE,_xlfn.UNIQUE(_xlfn.FILTER('기록'!$A:$A,(('기록'!$C:$C=H8)*('기록'!$A:$A>=$B$1)*('기록'!$A:$A<=$B$2)))))) | L8: =IF(H8="","",I8)
A9: =IFERROR(INDEX($N$5:$Q$204,5,1),"") | B9: =IFERROR(INDEX($N$5:$Q$204,5,2),"") | C9: =IFERROR(INDEX($N$5:$Q$204,5,3),"") | D9: =IFERROR(INDEX($N$5:$Q$204,5,4),"") | H9: =IFERROR(INDEX(_xlfn.UNIQUE(_xlfn.FILTER('기록'!$C$2:$C$181,('기록'!$C$2:$C$181<>"")*('기록'!$A$2:$A$181>=$B$1)*('기록'!$A$2:$A$181<=$B$2))),5),"") | I9: =IF(H9="","",COUNTA(_xlfn.UNIQUE(_xlfn.FILTER('기록'!$A:$A,(('기록'!$C:$C=H9)*('기록'!$A:$A>=$B$1)*('기록'!$A:$A<=$B$2)))))) | J9: =IF(H9="","",COUNTIFS('기록'!$C:$C,H9,'기록'!$A:$A,">="&$B$1,'기록'!$A:$A,"<="&$B$2)) | K9: =IF(H9="","",_xlfn.TEXTJOIN(", ",TRUE,_xlfn.UNIQUE(_xlfn.FILTER('기록'!$A:$A,(('기록'!$C:$C=H9)*('기록'!$A:$A>=$B$1)*('기록'!$A:$A<=$B$2)))))) | L9: =IF(H9="","",I9)
A10: =IFERROR(INDEX($N$5:$Q$204,6,1),"") | B10: =IFERROR(INDEX($N$5:$Q$204,6,2),"") | C10: =IFERROR(INDEX($N$5:$Q$204,6,3),"") | D10: =IFERROR(INDEX($N$5:$Q$204,6,4),"") | H10: =IFERROR(INDEX(_xlfn.UNIQUE(_xlfn.FILTER('기록'!$C$2:$C$181,('기록'!$C$2:$C$181<>"")*('기록'!$A$2:$A$181>=$B$1)*('기록'!$A$2:$A$181<=$B$2))),6),"") | I10: =IF(H10="","",COUNTA(_xlfn.UNIQUE(_xlfn.FILTER('기록'!$A:$A,(('기록'!$C:$C=H10)*('기록'!$A:$A>=$B$1)*('기록'!$A:$A<=$B$2)))))) | J10: =IF(H10="","",COUNTIFS('기록'!$C:$C,H10,'기록'!$A:$A,">="&$B$1,'기록'!$A:$A,"<="&$B$2)) | K10: =IF(H10="","",_xlfn.TEXTJOIN(", ",TRUE,_xlfn.UNIQUE(_xlfn.FILTER('기록'!$A:$A,(('기록'!$C:$C=H10)*('기록'!$A:$A>=$B$1)*('기록'!$A:$A<=$B$2)))))) | L10: =IF(H10="","",I10)
A11: =IFERROR(INDEX($N$5:$Q$204,7,1),"") | B11: =IFERROR(INDEX($N$5:$Q$204,7,2),"") | C11: =IFERROR(INDEX($N$5:$Q$204,7,3),"") | D11: =IFERROR(INDEX($N$5:$Q$204,7,4),"") | H11: =IFERROR(INDEX(_xlfn.UNIQUE(_xlfn.FILTER('기록'!$C$2:$C$181,('기록'!$C$2:$C$181<>"")*('기록'!$A$2:$A$181>=$B$1)*('기록'!$A$2:$A$181<=$B$2))),7),"") | I11: =IF(H11="","",COUNTA(_xlfn.UNIQUE(_xlfn.FILTER('기록'!$A:$A,(('기록'!$C:$C=H11)*('기록'!$A:$A>=$B$1)*('기록'!$A:$A<=$B$2)))))) | J11: =IF(H11="","",COUNTIFS('기록'!$C:$C,H11,'기록'!$A:$A,">="&$B$1,'기록'!$A:$A,"<="&$B$2)) | K11: =IF(H11="","",_xlfn.TEXTJOIN(", ",TRUE,_xlfn.UNIQUE(_xlfn.FILTER('기록'!$A:$A,(('기록'!$C:$C=H11)*('기록'!$A:$A>=$B$1)*('기록'!$A:$A<=$B$2)))))) | L11: =IF(H11="","",I11)
A12: =IFERROR(INDEX($N$5:$Q$204,8,1),"") | B12: =IFERROR(INDEX($N$5:$Q$204,8,2),"") | C12: =IFERROR(INDEX($N$5:$Q$204,8,3),"") | D12: =IFERROR(INDEX($N$5:$Q$204,8,4),"") | H12: =IFERROR(INDEX(_xlfn.UNIQUE(_xlfn.FILTER('기록'!$C$2:$C$181,('기록'!$C$2:$C$181<>"")*('기록'!$A$2:$A$181>=$B$1)*('기록'!$A$2:$A$181<=$B$2))),8),"") | I12: =IF(H12="","",COUNTA(_xlfn.UNIQUE(_xlfn.FILTER('기록'!$A:$A,(('기록'!$C:$C=H12)*('기록'!$A:$A>=$B$1)*('기록'!$A:$A<=$B$2)))))) | J12: =IF(H12="","",COUNTIFS('기록'!$C:$C,H12,'기록'!$A:$A,">="&$B$1,'기록'!$A:$A,"<="&$B$2)) | K12: =IF(H12="","",_xlfn.TEXTJOIN(", ",TRUE,_xlfn.UNIQUE(_xlfn.FILTER('기록'!$A:$A,(('기록'!$C:$C=H12)*('기록'!$A:$A>=$B$1)*('기록'!$A:$A<=$B$2)))))) | L12: =IF(H12="","",I12)
A13: =IFERROR(INDEX($N$5:$Q$204,9,1),"") | B13: =IFERROR(INDEX($N$5:$Q$204,9,2),"") | C13: =IFERROR(INDEX($N$5:$Q$204,9,3),"") | D13: =IFERROR(INDEX($N$5:$Q$204,9,4),"") | H13: =IFERROR(INDEX(_xlfn.UNIQUE(_xlfn.FILTER('기록'!$C$2:$C$181,('기록'!$C$2:$C$181<>"")*('기록'!$A$2:$A$181>=$B$1)*('기록'!$A$2:$A$181<=$B$2))),9),"") | I13: =IF(H13="","",COUNTA(_xlfn.UNIQUE(_xlfn.FILTER('기록'!$A:$A,(('기록'!$C:$C=H13)*('기록'!$A:$A>=$B$1)*('기록'!$A:$A<=$B$2)))))) | J13: =IF(H13="","",COUNTIFS('기록'!$C:$C,H13,'기록'!$A:$A,">="&$B$1,'기록'!$A:$A,"<="&$B$2)) | K13: =IF(H13="","",_xlfn.TEXTJOIN(", ",TRUE,_xlfn.UNIQUE(_xlfn.FILTER('기록'!$A:$A,(('기록'!$C:$C=H13)*('기록'!$A:$A>=$B$1)*('기록'!$A:$A<=$B$2)))))) | L13: =IF(H13="","",I13)
A14: =IFERROR(INDEX($N$5:$Q$204,10,1),"") | B14: =IFERROR(INDEX($N$5:$Q$204,10,2),"") | C14: =IFERROR(INDEX($N$5:$Q$204,10,3),"") | D14: =IFERROR(INDEX($N$5:$Q$204,10,4),"") | H14: =IFERROR(INDEX(_xlfn.UNIQUE(_xlfn.FILTER('기록'!$C$2:$C$181,('기록'!$C$2:$C$181<>"")*('기록'!$A$2:$A$181>=$B$1)*('기록'!$A$2:$A$181<=$B$2))),10),"") | I14: =IF(H14="","",COUNTA(_xlfn.UNIQUE(_xlfn.FILTER('기록'!$A:$A,(('기록'!$C:$C=H14)*('기록'!$A:$A>=$B$1)*('기록'!$A:$A<=$B$2)))))) | J14: =IF(H14="","",COUNTIFS('기록'!$C:$C,H14,'기록'!$A:$A,">="&$B$1,'기록'!$A:$A,"<="&$B$2)) | K14: =IF(H14="","",_xlfn.TEXTJOIN(", ",TRUE,_xlfn.UNIQUE(_xlfn.FILTER('기록'!$A:$A,(('기록'!$C:$C=H14)*('기록'!$A:$A>=$B$1)*('기록'!$A:$A<=$B$2)))))) | L14: =IF(H14="","",I14)
A15: =IFERROR(INDEX($N$5:$Q$204,11,1),"") | B15: =IFERROR(INDEX($N$5:$Q$204,11,2),"") | C15: =IFERROR(INDEX($N$5:$Q$204,11,3),"") | D15: =IFERROR(INDEX($N$5:$Q$204,11,4),"") | H15: =IFERROR(INDEX(_xlfn.UNIQUE(_xlfn.FILTER('기록'!$C$2:$C$181,('기록'!$C$2:$C$181<>"")*('기록'!$A$2:$A$181>=$B$1)*('기록'!$A$2:$A$181<=$B$2))),11),"") | I15: =IF(H15="","",COUNTA(_xlfn.UNIQUE(_xlfn.FILTER('기록'!$A:$A,(('기록'!$C:$C=H15)*('기록'!$A:$A>=$B$1)*('기록'!$A:$A<=$B$2)))))) | J15: =IF(H15="","",COUNTIFS('기록'!$C:$C,H15,'기록'!$A:$A,">="&$B$1,'기록'!$A:$A,"<="&$B$2)) | K15: =IF(H15="","",_xlfn.TEXTJOIN(", ",TRUE,_xlfn.UNIQUE(_xlfn.FILTER('기록'!$A:$A,(('기록'!$C:$C=H15)*('기록'!$A:$A>=$B$1)*('기록'!$A:$A<=$B$2)))))) | L15: =IF(H15="","",I15)
A16: =IFERROR(INDEX($N$5:$Q$204,12,1),"") | B16: =IFERROR(INDEX($N$5:$Q$204,12,2),"") | C16: =IFERROR(INDEX($N$5:$Q$204,12,3),"") | D16: =IFERROR(INDEX($N$5:$Q$204,12,4),"") | H16: =IFERROR(INDEX(_xlfn.UNIQUE(_xlfn.FILTER('기록'!$C$2:$C$181,('기록'!$C$2:$C$181<>"")*('기록'!$A$2:$A$181>=$B$1)*('기록'!$A$2:$A$181<=$B$2))),12),"") | I16: =IF(H16="","",COUNTA(_xlfn.UNIQUE(_xlfn.FILTER('기록'!$A:$A,(('기록'!$C:$C=H16)*('기록'!$A:$A>=$B$1)*('기록'!$A:$A<=$B$2)))))) | J16: =IF(H16="","",COUNTIFS('기록'!$C:$C,H16,'기록'!$A:$A,">="&$B$1,'기록'!$A:$A,"<="&$B$2)) | K16: =IF(H16="","",_xlfn.TEXTJOIN(", ",TRUE,_xlfn.UNIQUE(_xlfn.FILTER('기록'!$A:$A,(('기록'!$C:$C=H16)*('기록'!$A:$A>=$B$1)*('기록'!$A:$A<=$B$2)))))) | L16: =IF(H16="","",I16)
A17: =IFERROR(INDEX($N$5:$Q$204,13,1),"") | B17: =IFERROR(INDEX($N$5:$Q$204,13,2),"") | C17: =IFERROR(INDEX($N$5:$Q$204,13,3),"") | D17: =IFERROR(INDEX($N$5:$Q$204,13,4),"") | H17: =IFERROR(INDEX(_xlfn.UNIQUE(_xlfn.FILTER('기록'!$C$2:$C$181,('기록'!$C$2:$C$181<>"")*('기록'!$A$2:$A$181>=$B$1)*('기록'!$A$2:$A$181<=$B$2))),13),"") | I17: =IF(H17="","",COUNTA(_xlfn.UNIQUE(_xlfn.FILTER('기록'!$A:$A,(('기록'!$C:$C=H17)*('기록'!$A:$A>=$B$1)*('기록'!$A:$A<=$B$2)))))) | J17: =IF(H17="","",COUNTIFS('기록'!$C:$C,H17,'기록'!$A:$A,">="&$B$1,'기록'!$A:$A,"<="&$B$2)) | K17: =IF(H17="","",_xlfn.TEXTJOIN(", ",TRUE,_xlfn.UNIQUE(_xlfn.FILTER('기록'!$A:$A,(('기록'!$C:$C=H17)*('기록'!$A:$A>=$B$1)*('기록'!$A:$A<=$B$2)))))) | L17: =IF(H17="","",I17)
A18: =IFERROR(INDEX($N$5:$Q$204,14,1),"") | B18: =IFERROR(INDEX($N$5:$Q$204,14,2),"") | C18: =IFERROR(INDEX($N$5:$Q$204,14,3),"") | D18: =IFERROR(INDEX($N$5:$Q$204,14,4),"") | H18: =IFERROR(INDEX(_xlfn.UNIQUE(_xlfn.FILTER('기록'!$C$2:$C$181,('기록'!$C$2:$C$181<>"")*('기록'!$A$2:$A$181>=$B$1)*('기록'!$A$2:$A$181<=$B$2))),14),"") | I18: =IF(H18="","",COUNTA(_xlfn.UNIQUE(_xlfn.FILTER('기록'!$A:$A,(('기록'!$C:$C=H18)*('기록'!$A:$A>=$B$1)*('기록'!$A:$A<=$B$2)))))) | J18: =IF(H18="","",COUNTIFS('기록'!$C:$C,H18,'기록'!$A:$A,">="&$B$1,'기록'!$A:$A,"<="&$B$2)) | K18: =IF(H18="","",_xlfn.TEXTJOIN(", ",TRUE,_xlfn.UNIQUE(_xlfn.FILTER('기록'!$A:$A,(('기록'!$C:$C=H18)*('기록'!$A:$A>=$B$1)*('기록'!$A:$A<=$B$2)))))) | L18: =IF(H18="","",I18)
A19: =IFERROR(INDEX($N$5:$Q$204,15,1),"") | B19: =IFERROR(INDEX($N$5:$Q$204,15,2),"") | C19: =IFERROR(INDEX($N$5:$Q$204,15,3),"") | D19: =IFERROR(INDEX($N$5:$Q$204,15,4),"") | H19: =IFERROR(INDEX(_xlfn.UNIQUE(_xlfn.FILTER('기록'!$C$2:$C$181,('기록'!$C$2:$C$181<>"")*('기록'!$A$2:$A$181>=$B$1)*('기록'!$A$2:$A$181<=$B$2))),15),"") | I19: =IF(H19="","",COUNTA(_xlfn.UNIQUE(_xlfn.FILTER('기록'!$A:$A,(('기록'!$C:$C=H19)*('기록'!$A:$A>=$B$1)*('기록'!$A:$A<=$B$2)))))) | J19: =IF(H19="","",COUNTIFS('기록'!$C:$C,H19,'기록'!$A:$A,">="&$B$1,'기록'!$A:$A,"<="&$B$2)) | K19: =IF(H19="","",_xlfn.TEXTJOIN(", ",TRUE,_xlfn.UNIQUE(_xlfn.FILTER('기록'!$A:$A,(('기록'!$C:$C=H19)*('기록'!$A:$A>=$B$1)*('기록'!$A:$A<=$B$2)))))) | L19: =IF(H19="","",I19)
A20: =IFERROR(INDEX($N$5:$Q$204,16,1),"") | B20: =IFERROR(INDEX($N$5:$Q$204,16,2),"") | C20: =IFERROR(INDEX($N$5:$Q$204,16,3),"") | D20: =IFERROR(INDEX($N$5:$Q$204,16,4),"") | H20: =IFERROR(INDEX(_xlfn.UNIQUE(_xlfn.FILTER('기록'!$C$2:$C$181,('기록'!$C$2:$C$181<>"")*('기록'!$A$2:$A$181>=$B$1)*('기록'!$A$2:$A$181<=$B$2))),16),"") | I20: =IF(H20="","",COUNTA(_xlfn.UNIQUE(_xlfn.FILTER('기록'!$A:$A,(('기록'!$C:$C=H20)*('기록'!$A:$A>=$B$1)*('기록'!$A:$A<=$B$2)))))) | J20: =IF(H20="","",COUNTIFS('기록'!$C:$C,H20,'기록'!$A:$A,">="&$B$1,'기록'!$A:$A,"<="&$B$2)) | K20: =IF(H20="","",_xlfn.TEXTJOIN(", ",TRUE,_xlfn.UNIQUE(_xlfn.FILTER('기록'!$A:$A,(('기록'!$C:$C=H20)*('기록'!$A:$A>=$B$1)*('기록'!$A:$A<=$B$2)))))) | L20: =IF(H20="","",I20)
A21: =IFERROR(INDEX($N$5:$Q$204,17,1),"") | B21: =IFERROR(INDEX($N$5:$Q$204,17,2),"") | C21: =IFERROR(INDEX($N$5:$Q$204,17,3),"") | D21: =IFERROR(INDEX($N$5:$Q$204,17,4),"") | H21: =IFERROR(INDEX(_xlfn.UNIQUE(_xlfn.FILTER('기록'!$C$2:$C$181,('기록'!$C$2:$C$181<>"")*('기록'!$A$2:$A$181>=$B$1)*('기록'!$A$2:$A$181<=$B$2))),17),"") | I21: =IF(H21="","",COUNTA(_xlfn.UNIQUE(_xlfn.FILTER('기록'!$A:$A,(('기록'!$C:$C=H21)*('기록'!$A:$A>=$B$1)*('기록'!$A:$A<=$B$2)))))) | J21: =IF(H21="","",COUNTIFS('기록'!$C:$C,H21,'기록'!$A:$A,">="&$B$1,'기록'!$A:$A,"<="&$B$2)) | K21: =IF(H21="","",_xlfn.TEXTJOIN(", ",TRUE,_xlfn.UNIQUE(_xlfn.FILTER('기록'!$A:$A,(('기록'!$C:$C=H21)*('기록'!$A:$A>=$B$1)*('기록'!$A:$A<=$B$2)))))) | L21: =IF(H21="","",I21)
A22: =IFERROR(INDEX($N$5:$Q$204,18,1),"") | B22: =IFERROR(INDEX($N$5:$Q$204,18,2),"") | C22: =IFERROR(INDEX($N$5:$Q$204,18,3),"") | D22: =IFERROR(INDEX($N$5:$Q$204,18,4),"") | H22: =IFERROR(INDEX(_xlfn.UNIQUE(_xlfn.FILTER('기록'!$C$2:$C$181,('기록'!$C$2:$C$181<>"")*('기록'!$A$2:$A$181>=$B$1)*('기록'!$A$2:$A$181<=$B$2))),18),"") | I22: =IF(H22="","",COUNTA(_xlfn.UNIQUE(_xlfn.FILTER('기록'!$A:$A,(('기록'!$C:$C=H22)*('기록'!$A:$A>=$B$1)*('기록'!$A:$A<=$B$2)))))) | J22: =IF(H22="","",COUNTIFS('기록'!$C:$C,H22,'기록'!$A:$A,">="&$B$1,'기록'!$A:$A,"<="&$B$2)) | K22: =IF(H22="","",_xlfn.TEXTJOIN(", ",TRUE,_xlfn.UNIQUE(_xlfn.FILTER('기록'!$A:$A,(('기록'!$C:$C=H22)*('기록'!$A:$A>=$B$1)*('기록'!$A:$A<=$B$2)))))) | L22: =IF(H22="","",I22)
A23: =IFERROR(INDEX($N$5:$Q$204,19,1),"") | B23: =IFERROR(INDEX($N$5:$Q$204,19,2),"") | C23: =IFERROR(INDEX($N$5:$Q$204,19,3),"") | D23: =IFERROR(INDEX($N$5:$Q$204,19,4),"") | H23: =IFERROR(INDEX(_xlfn.UNIQUE(_xlfn.FILTER('기록'!$C$2:$C$181,('기록'!$C$2:$C$181<>"")*('기록'!$A$2:$A$181>=$B$1)*('기록'!$A$2:$A$181<=$B$2))),19),"") | I23: =IF(H23="","",COUNTA(_xlfn.UNIQUE(_xlfn.FILTER('기록'!$A:$A,(('기록'!$C:$C=H23)*('기록'!$A:$A>=$B$1)*('기록'!$A:$A<=$B$2)))))) | J23: =IF(H23="","",COUNTIFS('기록'!$C:$C,H23,'기록'!$A:$A,">="&$B$1,'기록'!$A:$A,"<="&$B$2)) | K23: =IF(H23="","",_xlfn.TEXTJOIN(", ",TRUE,_xlfn.UNIQUE(_xlfn.FILTER('기록'!$A:$A,(('기록'!$C:$C=H23)*('기록'!$A:$A>=$B$1)*('기록'!$A:$A<=$B$2)))))) | L23: =IF(H23="","",I23)
A24: =IFERROR(INDEX($N$5:$Q$204,20,1),"") | B24: =IFERROR(INDEX($N$5:$Q$204,20,2),"") | C24: =IFERROR(INDEX($N$5:$Q$204,20,3),"") | D24: =IFERROR(INDEX($N$5:$Q$204,20,4),"") | H24: =IFERROR(INDEX(_xlfn.UNIQUE(_xlfn.FILTER('기록'!$C$2:$C$181,('기록'!$C$2:$C$181<>"")*('기록'!$A$2:$A$181>=$B$1)*('기록'!$A$2:$A$181<=$B$2))),20),"") | I24: =IF(H24="","",COUNTA(_xlfn.UNIQUE(_xlfn.FILTER('기록'!$A:$A,(('기록'!$C:$C=H24)*('기록'!$A:$A>=$B$1)*('기록'!$A:$A<=$B$2)))))) | J24: =IF(H24="","",COUNTIFS('기록'!$C:$C,H24,'기록'!$A:$A,">="&$B$1,'기록'!$A:$A,"<="&$B$2)) | K24: =IF(H24="","",_xlfn.TEXTJOIN(", ",TRUE,_xlfn.UNIQUE(_xlfn.FILTER('기록'!$A:$A,(('기록'!$C:$C=H24)*('기록'!$A:$A>=$B$1)*('기록'!$A:$A<=$B$2)))))) | L24: =IF(H24="","",I24)
A25: =IFERROR(INDEX($N$5:$Q$204,21,1),"") | B25: =IFERROR(INDEX($N$5:$Q$204,21,2),"") | C25: =IFERROR(INDEX($N$5:$Q$204,21,3),"") | D25: =IFERROR(INDEX($N$5:$Q$204,21,4),"") | H25: =IFERROR(INDEX(_xlfn.UNIQUE(_xlfn.FILTER('기록'!$C$2:$C$181,('기록'!$C$2:$C$181<>"")*('기록'!$A$2:$A$181>=$B$1)*('기록'!$A$2:$A$181<=$B$2))),21),"") | I25: =IF(H25="","",COUNTA(_xlfn.UNIQUE(_xlfn.FILTER('기록'!$A:$A,(('기록'!$C:$C=H25)*('기록'!$A:$A>=$B$1)*('기록'!$A:$A<=$B$2)))))) | J25: =IF(H25="","",COUNTIFS('기록'!$C:$C,H25,'기록'!$A:$A,">="&$B$1,'기록'!$A:$A,"<="&$B$2)) | K25: =IF(H25="","",_xlfn.TEXTJOIN(", ",TRUE,_xlfn.UNIQUE(_xlfn.FILTER('기록'!$A:$A,(('기록'!$C:$C=H25)*('기록'!$A:$A>=$B$1)*('기록'!$A:$A<=$B$2)))))) | L25: =IF(H25="","",I25)
A26: =IFERROR(INDEX($N$5:$Q$204,22,1),"") | B26: =IFERROR(INDEX($N$5:$Q$204,22,2),"") | C26: =IFERROR(INDEX($N$5:$Q$204,22,3),"") | D26: =IFERROR(INDEX($N$5:$Q$204,22,4),"") | H26: =IFERROR(INDEX(_xlfn.UNIQUE(_xlfn.FILTER('기록'!$C$2:$C$181,('기록'!$C$2:$C$181<>"")*('기록'!$A$2:$A$181>=$B$1)*('기록'!$A$2:$A$181<=$B$2))),22),"") | I26: =IF(H26="","",COUNTA(_xlfn.UNIQUE(_xlfn.FILTER('기록'!$A:$A,(('기록'!$C:$C=H26)*('기록'!$A:$A>=$B$1)*('기록'!$A:$A<=$B$2)))))) | J26: =IF(H26="","",COUNTIFS('기록'!$C:$C,H26,'기록'!$A:$A,">="&$B$1,'기록'!$A:$A,"<="&$B$2)) | K26: =IF(H26="","",_xlfn.TEXTJOIN(", ",TRUE,_xlfn.UNIQUE(_xlfn.FILTER('기록'!$A:$A,(('기록'!$C:$C=H26)*('기록'!$A:$A>=$B$1)*('기록'!$A:$A<=$B$2)))))) | L26: =IF(H26="","",I26)
A27: =IFERROR(INDEX($N$5:$Q$204,23,1),"") | B27: =IFERROR(INDEX($N$5:$Q$204,23,2),"") | C27: =IFERROR(INDEX($N$5:$Q$204,23,3),"") | D27: =IFERROR(INDEX($N$5:$Q$204,23,4),"") | H27: =IFERROR(INDEX(_xlfn.UNIQUE(_xlfn.FILTER('기록'!$C$2:$C$181,('기록'!$C$2:$C$181<>"")*('기록'!$A$2:$A$181>=$B$1)*('기록'!$A$2:$A$181<=$B$2))),23),"") | I27: =IF(H27="","",COUNTA(_xlfn.UNIQUE(_xlfn.FILTER('기록'!$A:$A,(('기록'!$C:$C=H27)*('기록'!$A:$A>=$B$1)*('기록'!$A:$A<=$B$2)))))) | J27: =IF(H27="","",COUNTIFS('기록'!$C:$C,H27,'기록'!$A:$A,">="&$B$1,'기록'!$A:$A,"<="&$B$2)) | K27: =IF(H27="","",_xlfn.TEXTJOIN(", ",TRUE,_xlfn.UNIQUE(_xlfn.FILTER('기록'!$A:$A,(('기록'!$C:$C=H27)*('기록'!$A:$A>=$B$1)*('기록'!$A:$A<=$B$2)))))) | L27: =IF(H27="","",I27)
A28: =IFERROR(INDEX($N$5:$Q$204,24,1),"") | B28: =IFERROR(INDEX($N$5:$Q$204,24,2),"") | C28: =IFERROR(INDEX($N$5:$Q$204,24,3),"") | D28: =IFERROR(INDEX($N$5:$Q$204,24,4),"") | H28: =IFERROR(INDEX(_xlfn.UNIQUE(_xlfn.FILTER('기록'!$C$2:$C$181,('기록'!$C$2:$C$181<>"")*('기록'!$A$2:$A$181>=$B$1)*('기록'!$A$2:$A$181<=$B$2))),24),"") | I28: =IF(H28="","",COUNTA(_xlfn.UNIQUE(_xlfn.FILTER('기록'!$A:$A,(('기록'!$C:$C=H28)*('기록'!$A:$A>=$B$1)*('기록'!$A:$A<=$B$2)))))) | J28: =IF(H28="","",COUNTIFS('기록'!$C:$C,H28,'기록'!$A:$A,">="&$B$1,'기록'!$A:$A,"<="&$B$2)) | K28: =IF(H28="","",_xlfn.TEXTJOIN(", ",TRUE,_xlfn.UNIQUE(_xlfn.FILTER('기록'!$A:$A,(('기록'!$C:$C=H28)*('기록'!$A:$A>=$B$1)*('기록'!$A:$A<=$B$2)))))) | L28: =IF(H28="","",I28)
A29: =IFERROR(INDEX($N$5:$Q$204,25,1),"") | B29: =IFERROR(INDEX($N$5:$Q$204,25,2),"") | C29: =IFERROR(INDEX($N$5:$Q$204,25,3),"") | D29: =IFERROR(INDEX($N$5:$Q$204,25,4),"") | H29: =IFERROR(INDEX(_xlfn.UNIQUE(_xlfn.FILTER('기록'!$C$2:$C$181,('기록'!$C$2:$C$181<>"")*('기록'!$A$2:$A$181>=$B$1)*('기록'!$A$2:$A$181<=$B$2))),25),"") | I29: =IF(H29="","",COUNTA(_xlfn.UNIQUE(_xlfn.FILTER('기록'!$A:$A,(('기록'!$C:$C=H29)*('기록'!$A:$A>=$B$1)*('기록'!$A:$A<=$B$2)))))) | J29: =IF(H29="","",COUNTIFS('기록'!$C:$C,H29,'기록'!$A:$A,">="&$B$1,'기록'!$A:$A,"<="&$B$2)) | K29: =IF(H29="","",_xlfn.TEXTJOIN(", ",TRUE,_xlfn.UNIQUE(_xlfn.FILTER('기록'!$A:$A,(('기록'!$C:$C=H29)*('기록'!$A:$A>=$B$1)*('기록'!$A:$A<=$B$2)))))) | L29: =IF(H29="","",I29)
A30: =IFERROR(INDEX($N$5:$Q$204,26,1),"") | B30: =IFERROR(INDEX($N$5:$Q$204,26,2),"") | C30: =IFERROR(INDEX($N$5:$Q$204,26,3),"") | D30: =IFERROR(INDEX($N$5:$Q$204,26,4),"") | H30: =IFERROR(INDEX(_xlfn.UNIQUE(_xlfn.FILTER('기록'!$C$2:$C$181,('기록'!$C$2:$C$181<>"")*('기록'!$A$2:$A$181>=$B$1)*('기록'!$A$2:$A$181<=$B$2))),26),"") | I30: =IF(H30="","",COUNTA(_xlfn.UNIQUE(_xlfn.FILTER('기록'!$A:$A,(('기록'!$C:$C=H30)*('기록'!$A:$A>=$B$1)*('기록'!$A:$A<=$B$2)))))) | J30: =IF(H30="","",COUNTIFS('기록'!$C:$C,H30,'기록'!$A:$A,">="&$B$1,'기록'!$A:$A,"<="&$B$2)) | K30: =IF(H30="","",_xlfn.TEXTJOIN(", ",TRUE,_xlfn.UNIQUE(_xlfn.FILTER('기록'!$A:$A,(('기록'!$C:$C=H30)*('기록'!$A:$A>=$B$1)*('기록'!$A:$A<=$B$2)))))) | L30: =IF(H30="","",I30)
A31: =IFERROR(INDEX($N$5:$Q$204,27,1),"") | B31: =IFERROR(INDEX($N$5:$Q$204,27,2),"") | C31: =IFERROR(INDEX($N$5:$Q$204,27,3),"") | D31: =IFERROR(INDEX($N$5:$Q$204,27,4),"") | H31: =IFERROR(INDEX(_xlfn.UNIQUE(_xlfn.FILTER('기록'!$C$2:$C$181,('기록'!$C$2:$C$181<>"")*('기록'!$A$2:$A$181>=$B$1)*('기록'!$A$2:$A$181<=$B$2))),27),"") | I31: =IF(H31="","",COUNTA(_xlfn.UNIQUE(_xlfn.FILTER('기록'!$A:$A,(('기록'!$C:$C=H31)*('기록'!$A:$A>=$B$1)*('기록'!$A:$A<=$B$2)))))) | J31: =IF(H31="","",COUNTIFS('기록'!$C:$C,H31,'기록'!$A:$A,">="&$B$1,'기록'!$A:$A,"<="&$B$2)) | K31: =IF(H31="","",_xlfn.TEXTJOIN(", ",TRUE,_xlfn.UNIQUE(_xlfn.FILTER('기록'!$A:$A,(('기록'!$C:$C=H31)*('기록'!$A:$A>=$B$1)*('기록'!$A:$A<=$B$2)))))) | L31: =IF(H31="","",I31)
A32: =IFERROR(INDEX($N$5:$Q$204,28,1),"") | B32: =IFERROR(INDEX($N$5:$Q$204,28,2),"") | C32: =IFERROR(INDEX($N$5:$Q$204,28,3),"") | D32: =IFERROR(INDEX($N$5:$Q$204,28,4),"") | H32: =IFERROR(INDEX(_xlfn.UNIQUE(_xlfn.FILTER('기록'!$C$2:$C$181,('기록'!$C$2:$C$181<>"")*('기록'!$A$2:$A$181>=$B$1)*('기록'!$A$2:$A$181<=$B$2))),28),"") | I32: =IF(H32="","",COUNTA(_xlfn.UNIQUE(_xlfn.FILTER('기록'!$A:$A,(('기록'!$C:$C=H32)*('기록'!$A:$A>=$B$1)*('기록'!$A:$A<=$B$2)))))) | J32: =IF(H32="","",COUNTIFS('기록'!$C:$C,H32,'기록'!$A:$A,">="&$B$1,'기록'!$A:$A,"<="&$B$2)) | K32: =IF(H32="","",_xlfn.TEXTJOIN(", ",TRUE,_xlfn.UNIQUE(_xlfn.FILTER('기록'!$A:$A,(('기록'!$C:$C=H32)*('기록'!$A:$A>=$B$1)*('기록'!$A:$A<=$B$2)))))) | L32: =IF(H32="","",I32)
A33: =IFERROR(INDEX($N$5:$Q$204,29,1),"") | B33: =IFERROR(INDEX($N$5:$Q$204,29,2),"") | C33: =IFERROR(INDEX($N$5:$Q$204,29,3),"") | D33: =IFERROR(INDEX($N$5:$Q$204,29,4),"") | H33: =IFERROR(INDEX(_xlfn.UNIQUE(_xlfn.FILTER('기록'!$C$2:$C$181,('기록'!$C$2:$C$181<>"")*('기록'!$A$2:$A$181>=$B$1)*('기록'!$A$2:$A$181<=$B$2))),29),"") | I33: =IF(H33="","",COUNTA(_xlfn.UNIQUE(_xlfn.FILTER('기록'!$A:$A,(('기록'!$C:$C=H33)*('기록'!$A:$A>=$B$1)*('기록'!$A:$A<=$B$2)))))) | J33: =IF(H33="","",COUNTIFS('기록'!$C:$C,H33,'기록'!$A:$A,">="&$B$1,'기록'!$A:$A,"<="&$B$2)) | K33: =IF(H33="","",_xlfn.TEXTJOIN(", ",TRUE,_xlfn.UNIQUE(_xlfn.FILTER('기록'!$A:$A,(('기록'!$C:$C=H33)*('기록'!$A:$A>=$B$1)*('기록'!$A:$A<=$B$2)))))) | L33: =IF(H33="","",I33)
A34: =IFERROR(INDEX($N$5:$Q$204,30,1),"") | B34: =IFERROR(INDEX($N$5:$Q$204,30,2),"") | C34: =IFERROR(INDEX($N$5:$Q$204,30,3),"") | D34: =IFERROR(INDEX($N$5:$Q$204,30,4),"") | H34: =IFERROR(INDEX(_xlfn.UNIQUE(_xlfn.FILTER('기록'!$C$2:$C$181,('기록'!$C$2:$C$181<>"")*('기록'!$A$2:$A$181>=$B$1)*('기록'!$A$2:$A$181<=$B$2))),30),"") | I34: =IF(H34="","",COUNTA(_xlfn.UNIQUE(_xlfn.FILTER('기록'!$A:$A,(('기록'!$C:$C=H34)*('기록'!$A:$A>=$B$1)*('기록'!$A:$A<=$B$2)))))) | J34: =IF(H34="","",COUNTIFS('기록'!$C:$C,H34,'기록'!$A:$A,">="&$B$1,'기록'!$A:$A,"<="&$B$2)) | K34: =IF(H34="","",_xlfn.TEXTJOIN(", ",TRUE,_xlfn.UNIQUE(_xlfn.FILTER('기록'!$A:$A,(('기록'!$C:$C=H34)*('기록'!$A:$A>=$B$1)*('기록'!$A:$A<=$B$2)))))) | L34: =IF(H34="","",I34)
A35: =IFERROR(INDEX($N$5:$Q$204,31,1),"") | B35: =IFERROR(INDEX($N$5:$Q$204,31,2),"") | C35: =IFERROR(INDEX($N$5:$Q$204,31,3),"") | D35: =IFERROR(INDEX($N$5:$Q$204,31,4),"") | H35: =IFERROR(INDEX(_xlfn.UNIQUE(_xlfn.FILTER('기록'!$C$2:$C$181,('기록'!$C$2:$C$181<>"")*('기록'!$A$2:$A$181>=$B$1)*('기록'!$A$2:$A$181<=$B$2))),31),"") | I35: =IF(H35="","",COUNTA(_xlfn.UNIQUE(_xlfn.FILTER('기록'!$A:$A,(('기록'!$C:$C=H35)*('기록'!$A:$A>=$B$1)*('기록'!$A:$A<=$B$2)))))) | J35: =IF(H35="","",COUNTIFS('기록'!$C:$C,H35,'기록'!$A:$A,">="&$B$1,'기록'!$A:$A,"<="&$B$2)) | K35: =IF(H35="","",_xlfn.TEXTJOIN(", ",TRUE,_xlfn.UNIQUE(_xlfn.FILTER('기록'!$A:$A,(('기록'!$C:$C=H35)*('기록'!$A:$A>=$B$1)*('기록'!$A:$A<=$B$2)))))) | L35: =IF(H35="","",I35)
A36: =IFERROR(INDEX($N$5:$Q$204,32,1),"") | B36: =IFERROR(INDEX($N$5:$Q$204,32,2),"") | C36: =IFERROR(INDEX($N$5:$Q$204,32,3),"") | D36: =IFERROR(INDEX($N$5:$Q$204,32,4),"") | H36: =IFERROR(INDEX(_xlfn.UNIQUE(_xlfn.FILTER('기록'!$C$2:$C$181,('기록'!$C$2:$C$181<>"")*('기록'!$A$2:$A$181>=$B$1)*('기록'!$A$2:$A$181<=$B$2))),32),"") | I36: =IF(H36="","",COUNTA(_xlfn.UNIQUE(_xlfn.FILTER('기록'!$A:$A,(('기록'!$C:$C=H36)*('기록'!$A:$A>=$B$1)*('기록'!$A:$A<=$B$2)))))) | J36: =IF(H36="","",COUNTIFS('기록'!$C:$C,H36,'기록'!$A:$A,">="&$B$1,'기록'!$A:$A,"<="&$B$2)) | K36: =IF(H36="","",_xlfn.TEXTJOIN(", ",TRUE,_xlfn.UNIQUE(_xlfn.FILTER('기록'!$A:$A,(('기록'!$C:$C=H36)*('기록'!$A:$A>=$B$1)*('기록'!$A:$A<=$B$2)))))) | L36: =IF(H36="","",I36)
A37: =IFERROR(INDEX($N$5:$Q$204,33,1),"") | B37: =IFERROR(INDEX($N$5:$Q$204,33,2),"") | C37: =IFERROR(INDEX($N$5:$Q$204,33,3),"") | D37: =IFERROR(INDEX($N$5:$Q$204,33,4),"") | H37: =IFERROR(INDEX(_xlfn.UNIQUE(_xlfn.FILTER('기록'!$C$2:$C$181,('기록'!$C$2:$C$181<>"")*('기록'!$A$2:$A$181>=$B$1)*('기록'!$A$2:$A$181<=$B$2))),33),"") | I37: =IF(H37="","",COUNTA(_xlfn.UNIQUE(_xlfn.FILTER('기록'!$A:$A,(('기록'!$C:$C=H37)*('기록'!$A:$A>=$B$1)*('기록'!$A:$A<=$B$2)))))) | J37: =IF(H37="","",COUNTIFS('기록'!$C:$C,H37,'기록'!$A:$A,">="&$B$1,'기록'!$A:$A,"<="&$B$2)) | K37: =IF(H37="","",_xlfn.TEXTJOIN(", ",TRUE,_xlfn.UNIQUE(_xlfn.FILTER('기록'!$A:$A,(('기록'!$C:$C=H37)*('기록'!$A:$A>=$B$1)*('기록'!$A:$A<=$B$2)))))) | L37: =IF(H37="","",I37)
A38: =IFERROR(INDEX($N$5:$Q$204,34,1),"") | B38: =IFERROR(INDEX($N$5:$Q$204,34,2),"") | C38: =IFERROR(INDEX($N$5:$Q$204,34,3),"") | D38: =IFERROR(INDEX($N$5:$Q$204,34,4),"") | H38: =IFERROR(INDEX(_xlfn.UNIQUE(_xlfn.FILTER('기록'!$C$2:$C$181,('기록'!$C$2:$C$181<>"")*('기록'!$A$2:$A$181>=$B$1)*('기록'!$A$2:$A$181<=$B$2))),34),"") | I38: =IF(H38="","",COUNTA(_xlfn.UNIQUE(_xlfn.FILTER('기록'!$A:$A,(('기록'!$C:$C=H38)*('기록'!$A:$A>=$B$1)*('기록'!$A:$A<=$B$2)))))) | J38: =IF(H38="","",COUNTIFS('기록'!$C:$C,H38,'기록'!$A:$A,">="&$B$1,'기록'!$A:$A,"<="&$B$2)) | K38: =IF(H38="","",_xlfn.TEXTJOIN(", ",TRUE,_xlfn.UNIQUE(_xlfn.FILTER('기록'!$A:$A,(('기록'!$C:$C=H38)*('기록'!$A:$A>=$B$1)*('기록'!$A:$A<=$B$2)))))) | L38: =IF(H38="","",I38)
